Workbook
Name db_fifarank: Settings!$B$19:$C$66
Name gmt_delta: Settings!$G$16
Name group_round_completed: '2026 World Cup'!$AS$92
Name lang: Settings!$G$15
Name lang_list: T!$1:$1
Name my_team: Settings!$I$15
Name T: T!$1:$1048576
Name teams: Settings!$I$17:$I$64

Sheet T
A1: English | B1: Albanian | C1: Arabic | D1: Armenian | E1: Azerbaijan | F1: Bulgarian | G1: Català | H1: Chinese (Simplified) | I1: Chinese (Traditional) | J1: Croatian | K1: Czech | L1: Danish | M1: Dutch | N1: Faroese | O1: French | P1: Georgian | Q1: German | R1: Greek | S1: Hebrew | T1: Hungarian | U1: Indonesia | V1: Icelandic | W1: Italian | X1: Korean | Y1: Lithuanian | Z1: Macedonian | AA1: Maltese | AB1: Norwegian | AC1: Persian | AD1: Polish | AE1: Portuguese | AF1: Romanian | AG1: Serbian | AH1: Slovak | AI1: Slovenian | AJ1: Spanish | AK1: Swedish | AL1: Thai | AM1: Turkish | AN1: Vietnamese | AO1: Ukrainian | AP1: Urdu
A2: 2026 World Cup Final Tournament Schedule | B2: Kupa Botërore 2026 | C2: جدول مباريات كأس العالم 2026 | D2: Աշխարհի 2026թ. առաջնություն | E2: 2026 - cu il Dünya Çempionatinin Final Mərhələsinin Cədvəli | F2: График на срещите - Световно първенство 2026 | G2: Calendari de la Fase Final de la Copa del Món de futbol 2026 | H2: 巴西2026年世界杯 | I2: 2026 世界盃賽程 | J2: Svjetsko prvenstvo 2026 raspored utakmica | K2: Mistrovství světa ve fotbale 2026 | L2: 2026 Verdensmesterskabs Oversigt | M2: Wereldkampioenschap 2026 Toernooischema | N2: 2026 Heimsmeistarakappingaryvirlit | O2: Coupe du Monde de la FIFA 2026 - Calendrier des matchs | P2: მსოფლიო ჩემპიონატი ფეხბურთში - სამხრეთ აფრიკა 2026 | Q2: Spielplan Weltmeisterschafts endrunde 2026 | R2: Πρόγραμμα Τελικών Παγκοσμίου Κυπέλλου 2026 | S2: 2026 גביע העולם טורניר הגמר תזמן | T2: 2026 Labdarúgó-világbajnokság döntő sorozata | U2: Jadwal Turnamen Final Piala Dunia 2026 | V2: HM 2026 lokakeppnin | W2: Calendario Coppa del mondo 2026 | X2: 2026 월드컵 최종 토너먼트 일정 | Y2: 2026 Pasaulio Futbolo Čempionato Tvarkaraštis | Z2: Светско првенство 2026 - Распоред на натпревари | AA2: Skeda tat-Tazza tad-Dinja 2026 | AB2: Verdensmesterskapet i fotball 2026 | AC2: جدول مسابقات فینال جام جهانی 2026 | AD2: 2026 Mistrzostwa Świata Terminarz Meczów | AE2: Calendário Fase Final Mundial 2026 | AF2: Programul Turneului Final FIFA World Cup 2026 | AG2: Svetsko prvenstvo u fudbalu 2026 - Raspored utakmica | AH2: Majstrovstvá sveta vo futbale 2026 | AI2: Svetovno prvenstvo 2026 razpored tekem | AJ2: Copa Mundial de Fútbol - Brasil 2026 | AK2: Schema för VM-slutspelet 2026 | AL2: ตารางการแข่งขันฟุตบอลโลก 2026 | AM2: 2026 Dünya Kupası Finalleri Turnuva Fikstürü | AN2: Lịch Thi Đấu Cúp Bóng Đá Thế Giới 2026 | AO2: Календар Чемпіонату Світу 2026 | AP2: ۲۰۱۰ فٹبال عالمی کپ ٹورنمنٹ کا خاکہ
A3: Group Stage | B3: Grupet | C3: الدور الأول | D3: Խմբային փուլ | E3: Qrup Mərhələsi | F3: Групова фаза | G3: Fase de grups | H3: 小组赛阶段 | I3: 分組賽 | J3: Prvi krug | K3: Základní skupiny | L3: Gruppespil | M3: Groepsfase | N3: Bólkaspæl | O3: Phase de groupes | P3: ჯგუფური ეტაპი | Q3: Gruppenphase | R3: Φάση Ομίλων | S3: שלב הבתים | T3: Csoportkörök | U3: Babak Kualifikasi | V3: Riðlakeppnin | W3: Fase a gironi | X3: 조별 리그 | Y3: Grupės Etapas | Z3: Фаза по групи | AA3: Fażi tal-Gruppi | AB3: Gruppespill | AC3: مرحله گروهی | AD3: Faza Grupowa | AE3: Fase de grupos | AF3: Faza Grupelor | AG3: Grupno takmičenje | AH3: Skupinová fáza | AI3: Skupinski del | AJ3: Fase de grupos | AK3: Gruppspel | AL3: รอบแรก | AM3: Grup Aşaması | AN3: Vòng Bảng | AO3: Груповий етап | AP3: گروپ بندی
A4: Round of 16 | B4: Rundi I 16 | C4: دور الستة عشر | D4: 1/8 Եզրափակիչ | E4: 16-da bir raund | F4: 1/8 - финали | G4: Vuitens de final | H4: 16强赛 | I4: 十六強 | J4: Drugi krug | K4: Osmifinále | L4: Runde af 16 | M4: Achtste finales | N4: Áttandapartsfinala | O4: Huitièmes de finale | P4: მერვედფინალი | Q4: Achtelfinale | R4: Φάση των 16 | S4: שמינית גמר | T4: Nyolcaddöntők | U4: Per Delapan Final | V4: 16 liða úrslit | W4: Ottavi di finale | X4: 16강전 | Y4: 16-tuko Raundas | Z4: 1/8 финале | AA4: L-Aħħar Sittax | AB4: 8-dels finale | AC4: یک هشتم نهائی | AD4: 1/8 Finału | AE4: Oitavos de Final | AF4: Optimi | AG4: Šesnaestina finala | AH4: Osemfinále | AI4: Osminafinala | AJ4: Octavos de final | AK4: Åttondelsfinal | AL4: รอบสอง | AM4: Son 16 | AN4: Vòng 1/16 | AO4: 1/8 фіналу | AP4: سولھواں دور
A5: Quarterfinals | B5: Qerekfinalja | C5: دور الربع نهائي | D5: 1/4 Եզրափակիչ | E5: Dörddə bir Final | F5: 1/4 - финали | G5: Quarts de final | H5: 8强赛 | I5: 八強 | J5: Četvrtfinale | K5: Čtvrtfinále | L5: Kvartfinale | M5: Kwartfinales | N5: Fjórðingsfinala | O5: Quart de Finale | P5: მეოთხედფინალი | Q5: Viertelfinale | R5: Προημιτελικοί | S5: רבע גמר | T5: Negyeddöntők | U5: Perempat Final | V5: 8 liða úrslit | W5: Quarti di finale | X5: 8강전 | Y5: Ketvirtfinaliai | Z5: 1/4 финале | AA5: Kwarti-Finali | AB5: Kvartfinale | AC5: یک چهارم نهائی | AD5: Ćwierćfinały | AE5: Quartos de Final | AF5: Sferturi de finala | AG5: Četvrtfinale | AH5: Štvrťfinále | AI5: Četrtfinale | AJ5: Cuartos de Final | AK5: Kvartsfinal | AL5: รอบก่อนรองชนะเลิศ | AM5: Çeyrek Final | AN5: Tứ kết | AO5: Чвертьфінал | AP5: کواٹر فائنل
A6: Semi-Finals | B6: Gjysmëfinalja | C6: دور النصف نهائي | D6: Կիսաեզրափակիչ | E6: Yarım Final | F6: 1/2 - финали | G6: Semifinals | H6: 半决赛 | I6: 準決賽 | J6: Polufinale | K6: Semifinále | L6: Semifinale | M6: Halve finales | N6: Hálvfinala | O6: Demi-Finale | P6: ნახევარფინალი | Q6: Halbfinale | R6: Ημιτελικοί | S6: חצי גמר | T6: Elődöntők | U6: Semi Final | V6: Undanúrslit | W6: Semifinali | X6: 준결승전 | Y6: Pusfinaliai | Z6: 1/2 финале | AA6: Semi-Finali | AB6: Semifinale | AC6: نیمه نهائی | AD6: Półfinały | AE6: Semi-final | AF6: Semifinale | AG6: Polufinale | AH6: Semifinále | AI6: Polfinale | AJ6: Semifinales | AK6: Semifinal | AL6: รอบรองชนะเลิศ | AM6: Yarı Final | AN6: Bán kết | AO6: Півфінал | AP6: سیمی فائنل
A7: Third-Place Play-Off | B7: Takimi për vendin e tretë | C7: تحديد المركزين الثالث والرابع | D7: 3-րդ տեղի համար եզրափակիչ | E7: Üçüncü Yer Uğrunda | F7: Мач за трето място | G7: 3r i 4t lloc | H7: 季军赛 | I7: 季軍賽 | J7: Za treće mjesto | K7: Zápas o 3.místo | L7: Tredjeplads Kamp | M7: Derde en vierde plaats | N7: Dystur um 3. pláss | O7: Match pour la troisième place | P7: მესამე ადგილი | Q7: Spiel um den dritten Platz | R7: Μικρός Τελικός | S7: מקום 3-4 | T7: Bronzmeccs | U7: Perebutan Tempat Ketiga | V7: Leikur um 3.sæti | W7: Finale 3°- 4° posto | X7: 3,4위전 | Y7: Rungtynės dėl Trečios Vietos | Z7: Натпревар за трето место | AA7: Final għat-Tielet u r-Raba' Post | AB7: Bronsefinale | AC7: رده بندی | AD7: Mecz o trzecie miejsce | AE7: 3º/4º lugar | AF7: Finala mica | AG7: Za treće mjesto | AH7: Zápas o 3. miesto | AI7: Za tretje mesto | AJ7: Tercer puesto | AK7: Match om tredje pris | AL7: รอบชิงที่ 3 | AM7: Üçüncülük Maçı | AN7: Tranh hạng 3 | AO7: Матч за третє місце | AP7: تیسرے مقام کے لئے کھیل
A8: Final | B8: Finalja | C8: المباراة النهائية | D8: Եզրափակիչ | E8: Final | F8: Финал | G8: Final | H8: 总决赛 | I8: 總決賽 | J8: Finale | K8: Finále | L8: Finale | M8: Finale | N8: Finala | O8: Finale | P8: ფინალი | Q8: Finale | R8: Τελικός | S8: גמר | T8: Döntő | U8: Final | V8: Úrslit | W8: Finale | X8: 결승전 | Y8: Finalas | Z8: Финале | AA8: Finali | AB8: Finale | AC8: فینال | AD8: Finał | AE8: Final | AF8: FINALA | AG8: Finale | AH8: Finále | AI8: Finale | AJ8: Final | AK8: Final | AL8: รอบชิงชนะเลิศ | AM8: Final | AN8: Chung Kết | AO8: Фінал | AP8: فائنل
A9: Group | B9: Grupi | C9: المجموعة | D9: Խումբ | E9: Qrup | F9: Група | G9: Grup | H9: 小组 | I9: 小組 | J9: Grupa | K9: Skupina | L9: Gruppe | M9: Groep | N9: Bólkur | O9: Groupe | P9: ჯგუფი | Q9: Gruppe | R9: Όμιλος | S9: בית | T9: Csoport | U9: Kelompok | V9: Riðill | W9: Gruppo | X9: 그룹 | Y9: Grupė | Z9: Група | AA9: Grupp | AB9: Gruppe | AC9: گروه | AD9: Grupa | AE9: Grupo | AF9: Grupa | AG9: Grupa | AH9: Skupina | AI9: Skupina | AJ9: Grupo | AK9: Grupp | AL9: สาย | AM9: Grup | AN9: Bảng | AO9: Група | AP9: گروپ بندی
A10: PL | B10: L | C10: لعب | D10: Խ | E10: O | F10: М | G10: J | H10: 场次 | I10: 賽 | J10: PL | K10: Z | L10: SP | M10: WG | N10: SP | O10: J | P10: თ | Q10: SP | R10: ΑΓ | S10: משחקים | T10: M | U10: Main | V10: L | W10: G | X10: 경기 | Y10: Žst | Z10: О | AA10: L | AB10: S | AC10: بازی | AD10: M | AE10: J | AF10: J | AG10: UT | AH10: Z | AI10: PL | AJ10: J | AK10: Sp | AL10: แข่ง | AM10: O | AN10: Trận | AO10: І | AP10: کھیلے گئے مقابلے
A11: W | B11: F | C11: فاز | D11: Հ | E11: Q | F11: П | G11: G | H11: 胜 | I11: 勝 | J11: W | K11: V | L11: V | M11: W | N11: V | O11: V | P11: მოგ | Q11: S | R11: Ν | S11: נצחונות | T11: GY | U11: Menang | V11: U | W11: V | X11: 승 | Y11: L | Z11: П | AA11: R | AB11: V | AC11: برد | AD11: Z | AE11: V | AF11: V | AG11: P | AH11: V | AI11: W | AJ11: G | AK11: V | AL11: ชนะ | AM11: G | AN11: T | AO11: В | AP11: جیت
A12: DRAW | B12: BAR | C12: تعادل | D12: Ո | E12: H | F12: Р | G12: E | H12: 平 | I12: 和 | J12: DRAW | K12: R | L12: Uafgjort | M12: G | N12: J | O12: DRAW | P12: ფრე | Q12: DRAW | R12: Ι | S12: תיקו | T12: D | U12: Seri | V12: Jafnt | W12: P | X12: 무 | Y12: Lyg | Z12: Н | AA12: I | AB12: T | AC12: مساوی | AD12: R | AE12: E | AF12: E | AG12: NER. | AH12: R | AI12: DRAW | AJ12: DRAW | AK12: O | AL12: เสมอ | AM12: B | AN12: H | AO12: Н | AP12: برابر
... A157: en | B157: sq | C157: ar | D157: hy | E157: az | F157: bg | G157: ca | H157: zh-CN | I157: zh-TW | J157: hr | K157: cs | L157: da | M157: nl | N157: fr | O157: fr | P157: ka | Q157: de | R157: el | S157: iw | T157: hu | U157: id | V157: is | W157: it | X157: ko | Y157: lt | Z157: mk | AA157: mt | AB157: no | AC157: fa | AD157: pl | AE157: pt | AF157: ro | AG157: sr | AH157: sk | AI157: sl | AJ157: es | AK157: sv | AL157: th | AM157: tr | AN157: vi | AO157: uk | AP157: ur

Sheet Survivor
A1: Name | B1: Round 1 | F1: Round 2 | J1: Round 3 | N1: Round 4 | R1: Round 5 | V1: Round 6 | Z1: Round 7 | AD1: Round 8
B2: Pick | E2: Opponent | F2: Pick | I2: Opponent | J2: Pick | M2: Opponent | N2: Pick | Q2: Opponent | R2: Pick | U2: Opponent | V2: Pick | Y2: Opponent | Z2: Pick | AC2: Opponent | AD2: Pick | AG2: Opponent
A3: Aidan | B3: Sweden | C3: =IFERROR(_xlfn.XLOOKUP(B3,Rounds!A$2:A$25,Rounds!B$2:B$25), _xlfn.XLOOKUP(B3,Rounds!D$2:D$25,Rounds!C$2:C$25)) -> 5 | D3: =IFERROR(_xlfn.XLOOKUP(B3,Rounds!A$2:A$25,Rounds!C$2:C$25), _xlfn.XLOOKUP(B3,Rounds!D$2:D$25,Rounds!B$2:B$25)) -> 1 | E3: =IFERROR(_xlfn.XLOOKUP(B3,Rounds!A$2:A$25,Rounds!D$2:D$25), _xlfn.XLOOKUP(B3,Rounds!D$2:D$25,Rounds!A$2:A$25)) -> Tunisia | F3: United States | G3: =IFERROR(_xlfn.XLOOKUP(F3,Rounds!E$2:E$25,Rounds!F$2:F$25), _xlfn.XLOOKUP(F3,Rounds!H$2:H$25,Rounds!G$2:G$25)) -> 2 | H3: =IFERROR(_xlfn.XLOOKUP(F3,Rounds!E$2:E$25,Rounds!G$2:G$25), _xlfn.XLOOKUP(F3,Rounds!H$2:H$25,Rounds!F$2:F$25)) -> 0 | I3: =IFERROR(_xlfn.XLOOKUP(F3,Rounds!E$2:E$25,Rounds!H$2:H$25), _xlfn.XLOOKUP(F3,Rounds!H$2:H$25,Rounds!E$2:E$25)) -> Australia | J3: Ivory Coast | K3: =IFERROR(_xlfn.XLOOKUP(J3,Rounds!I$2:I$25,Rounds!J$2:J$25), _xlfn.XLOOKUP(J3,Rounds!L$2:L$25,Rounds!K$2:K$25)) -> 2 | L3: =IFERROR(_xlfn.XLOOKUP(J3,Rounds!I$2:I$25,Rounds!K$2:K$25), _xlfn.XLOOKUP(J3,Rounds!L$2:L$25,Rounds!J$2:J$25)) -> 0 | M3: =IFERROR(_xlfn.XLOOKUP(J3,Rounds!I$2:I$25,Rounds!L$2:L$25), _xlfn.XLOOKUP(J3,Rounds!L$2:L$25,Rounds!I$2:I$25)) -> Curaçao | N3: Brazil | O3: =IFERROR(_xlfn.XLOOKUP(N3,Rounds!M$2:M$17,Rounds!N$2:N$17), _xlfn.XLOOKUP(N3,Rounds!P$2:P$17,Rounds!O$2:O$17)) -> 2 | P3: =IFERROR(_xlfn.XLOOKUP(N3,Rounds!M$2:M$17,Rounds!O$2:O$17), _xlfn.XLOOKUP(N3,Rounds!P$2:P$17,Rounds!N$2:N$17)) -> 1 | Q3: =IFERROR(_xlfn.XLOOKUP(N3,Rounds!M$2:M$17,Rounds!P$2:P$17), _xlfn.XLOOKUP(N3,Rounds!P$2:P$17,Rounds!M$2:M$17)) -> Japan | R3: Mexico | S3: =IFERROR(_xlfn.XLOOKUP(R3,Rounds!Q$2:Q$9,Rounds!R$2:R$9), _xlfn.XLOOKUP(R3,Rounds!T$2:T$9,Rounds!S$2:S$9)) -> 2 | T3: =IFERROR(_xlfn.XLOOKUP(R3,Rounds!Q$2:Q$9,Rounds!S$2:S$9), _xlfn.XLOOKUP(R3,Rounds!T$2:T$9,Rounds!R$2:R$9)) -> 3 | U3: =IFERROR(_xlfn.XLOOKUP(R3,Rounds!Q$2:Q$9,Rounds!T$2:T$9), _xlfn.XLOOKUP(R3,Rounds!T$2:T$9,Rounds!Q$2:Q$9)) -> England | W3: =IFERROR(_xlfn.XLOOKUP(V3,Rounds!U$2:U$5,Rounds!V$2:V$5), _xlfn.XLOOKUP(V3,Rounds!X$2:X$5,Rounds!W$2:W$5)) -> #N/A | X3: =IFERROR(_xlfn.XLOOKUP(V3,Rounds!U$2:U$5,Rounds!W$2:W$5), _xlfn.XLOOKUP(V3,Rounds!X$2:X$5,Rounds!V$2:V$5)) -> #N/A | Y3: =IFERROR(_xlfn.XLOOKUP(V3,Rounds!U$2:U$5,Rounds!X$2:X$5), _xlfn.XLOOKUP(V3,Rounds!X$2:X$5,Rounds!U$2:U$5)) -> #N/A | AA3: =IFERROR(_xlfn.XLOOKUP(Z3,Rounds!Y$2:Y$3,Rounds!Z$2:Z$3), _xlfn.XLOOKUP(Z3,Rounds!AB$2:AB$3,Rounds!AA$2:AA$3)) -> #N/A | AB3: =IFERROR(_xlfn.XLOOKUP(Z3,Rounds!Y$2:Y$3,Rounds!AA$2:AA$3), _xlfn.XLOOKUP(Z3,Rounds!AB$2:AB$3,Rounds!Z$2:Z$3)) -> #N/A | AC3: =IFERROR(_xlfn.XLOOKUP(Z3,Rounds!Y$2:Y$3,Rounds!AB$2:AB$3), _xlfn.XLOOKUP(Z3,Rounds!AB$2:AB$3,Rounds!Y$2:Y$3)) -> #N/A | AE3: {=IFERROR(_xlfn.XLOOKUP(AD3,Rounds!AC$2:AC$2,Rounds!AD$2:AD$2), _xlfn.XLOOKUP(AD3,Rounds!AF$2:AF$2,Rounds!AE$2:AE$2))} -> #N/A | AF3: {=IFERROR(_xlfn.XLOOKUP(AD3,Rounds!AC$2:AC$2,Rounds!AE$2:AE$2), _xlfn.XLOOKUP(AD3,Rounds!AF$2:AF$2,Rounds!AD$2:AD$2))} -> #N/A | AG3: {=IFERROR(_xlfn.XLOOKUP(AD3,Rounds!AC$2:AC$2,Rounds!AF$2:AF$2), _xlfn.XLOOKUP(AD3,Rounds!AF$2:AF$2,Rounds!AC$2:AC$2))} -> #N/A
A4: Rylan | B4: Switzerland | C4: =IFERROR(_xlfn.XLOOKUP(B4,Rounds!A$2:A$25,Rounds!B$2:B$25), _xlfn.XLOOKUP(B4,Rounds!D$2:D$25,Rounds!C$2:C$25)) -> 1 | D4: =IFERROR(_xlfn.XLOOKUP(B4,Rounds!A$2:A$25,Rounds!C$2:C$25), _xlfn.XLOOKUP(B4,Rounds!D$2:D$25,Rounds!B$2:B$25)) -> 1 | E4: =IFERROR(_xlfn.XLOOKUP(B4,Rounds!A$2:A$25,Rounds!D$2:D$25), _xlfn.XLOOKUP(B4,Rounds!D$2:D$25,Rounds!A$2:A$25)) -> Qatar | F4: Egypt | G4: =IFERROR(_xlfn.XLOOKUP(F4,Rounds!E$2:E$25,Rounds!F$2:F$25), _xlfn.XLOOKUP(F4,Rounds!H$2:H$25,Rounds!G$2:G$25)) -> 3 | H4: =IFERROR(_xlfn.XLOOKUP(F4,Rounds!E$2:E$25,Rounds!G$2:G$25), _xlfn.XLOOKUP(F4,Rounds!H$2:H$25,Rounds!F$2:F$25)) -> 1 | I4: =IFERROR(_xlfn.XLOOKUP(F4,Rounds!E$2:E$25,Rounds!H$2:H$25), _xlfn.XLOOKUP(F4,Rounds!H$2:H$25,Rounds!E$2:E$25)) -> New Zealand | J4: Morocco | K4: =IFERROR(_xlfn.XLOOKUP(J4,Rounds!I$2:I$25,Rounds!J$2:J$25), _xlfn.XLOOKUP(J4,Rounds!L$2:L$25,Rounds!K$2:K$25)) -> 4 | L4: =IFERROR(_xlfn.XLOOKUP(J4,Rounds!I$2:I$25,Rounds!K$2:K$25), _xlfn.XLOOKUP(J4,Rounds!L$2:L$25,Rounds!J$2:J$25)) -> 2 | M4: =IFERROR(_xlfn.XLOOKUP(J4,Rounds!I$2:I$25,Rounds!L$2:L$25), _xlfn.XLOOKUP(J4,Rounds!L$2:L$25,Rounds!I$2:I$25)) -> Haiti | N4: England | O4: =IFERROR(_xlfn.XLOOKUP(N4,Rounds!M$2:M$17,Rounds!N$2:N$17), _xlfn.XLOOKUP(N4,Rounds!P$2:P$17,Rounds!O$2:O$17)) -> 2 | P4: =IFERROR(_xlfn.XLOOKUP(N4,Rounds!M$2:M$17,Rounds!O$2:O$17), _xlfn.XLOOKUP(N4,Rounds!P$2:P$17,Rounds!N$2:N$17)) -> 1 | Q4: =IFERROR(_xlfn.XLOOKUP(N4,Rounds!M$2:M$17,Rounds!P$2:P$17), _xlfn.XLOOKUP(N4,Rounds!P$2:P$17,Rounds!M$2:M$17)) -> DR Congo | R4: Mexico | S4: =IFERROR(_xlfn.XLOOKUP(R4,Rounds!Q$2:Q$9,Rounds!R$2:R$9), _xlfn.XLOOKUP(R4,Rounds!T$2:T$9,Rounds!S$2:S$9)) -> 2 | T4: =IFERROR(_xlfn.XLOOKUP(R4,Rounds!Q$2:Q$9,Rounds!S$2:S$9), _xlfn.XLOOKUP(R4,Rounds!T$2:T$9,Rounds!R$2:R$9)) -> 3 | U4: =IFERROR(_xlfn.XLOOKUP(R4,Rounds!Q$2:Q$9,Rounds!T$2:T$9), _xlfn.XLOOKUP(R4,Rounds!T$2:T$9,Rounds!Q$2:Q$9)) -> England | W4: =IFERROR(_xlfn.XLOOKUP(V4,Rounds!U$2:U$5,Rounds!V$2:V$5), _xlfn.XLOOKUP(V4,Rounds!X$2:X$5,Rounds!W$2:W$5)) -> #N/A | X4: =IFERROR(_xlfn.XLOOKUP(V4,Rounds!U$2:U$5,Rounds!W$2:W$5), _xlfn.XLOOKUP(V4,Rounds!X$2:X$5,Rounds!V$2:V$5)) -> #N/A | Y4: =IFERROR(_xlfn.XLOOKUP(V4,Rounds!U$2:U$5,Rounds!X$2:X$5), _xlfn.XLOOKUP(V4,Rounds!X$2:X$5,Rounds!U$2:U$5)) -> #N/A | AA4: =IFERROR(_xlfn.XLOOKUP(Z4,Rounds!Y$2:Y$3,Rounds!Z$2:Z$3), _xlfn.XLOOKUP(Z4,Rounds!AB$2:AB$3,Rounds!AA$2:AA$3)) -> #N/A | AB4: =IFERROR(_xlfn.XLOOKUP(Z4,Rounds!Y$2:Y$3,Rounds!AA$2:AA$3), _xlfn.XLOOKUP(Z4,Rounds!AB$2:AB$3,Rounds!Z$2:Z$3)) -> #N/A | AC4: =IFERROR(_xlfn.XLOOKUP(Z4,Rounds!Y$2:Y$3,Rounds!AB$2:AB$3), _xlfn.XLOOKUP(Z4,Rounds!AB$2:AB$3,Rounds!Y$2:Y$3)) -> #N/A | AE4: {=IFERROR(_xlfn.XLOOKUP(AD4,Rounds!AC$2:AC$2,Rounds!AD$2:AD$2), _xlfn.XLOOKUP(AD4,Rounds!AF$2:AF$2,Rounds!AE$2:AE$2))} -> #N/A | AF4: {=IFERROR(_xlfn.XLOOKUP(AD4,Rounds!AC$2:AC$2,Rounds!AE$2:AE$2), _xlfn.XLOOKUP(AD4,Rounds!AF$2:AF$2,Rounds!AD$2:AD$2))} -> #N/A | AG4: {=IFERROR(_xlfn.XLOOKUP(AD4,Rounds!AC$2:AC$2,Rounds!AF$2:AF$2), _xlfn.XLOOKUP(AD4,Rounds!AF$2:AF$2,Rounds!AC$2:AC$2))} -> #N/A
A5: Kenzie | B5: Colombia | C5: =IFERROR(_xlfn.XLOOKUP(B5,Rounds!A$2:A$25,Rounds!B$2:B$25), _xlfn.XLOOKUP(B5,Rounds!D$2:D$25,Rounds!C$2:C$25)) -> 3 | D5: =IFERROR(_xlfn.XLOOKUP(B5,Rounds!A$2:A$25,Rounds!C$2:C$25), _xlfn.XLOOKUP(B5,Rounds!D$2:D$25,Rounds!B$2:B$25)) -> 1 | E5: =IFERROR(_xlfn.XLOOKUP(B5,Rounds!A$2:A$25,Rounds!D$2:D$25), _xlfn.XLOOKUP(B5,Rounds!D$2:D$25,Rounds!A$2:A$25)) -> Uzbekistan | F5: Ecuador | G5: =IFERROR(_xlfn.XLOOKUP(F5,Rounds!E$2:E$25,Rounds!F$2:F$25), _xlfn.XLOOKUP(F5,Rounds!H$2:H$25,Rounds!G$2:G$25)) -> 0 | H5: =IFERROR(_xlfn.XLOOKUP(F5,Rounds!E$2:E$25,Rounds!G$2:G$25), _xlfn.XLOOKUP(F5,Rounds!H$2:H$25,Rounds!F$2:F$25)) -> 0 | I5: =IFERROR(_xlfn.XLOOKUP(F5,Rounds!E$2:E$25,Rounds!H$2:H$25), _xlfn.XLOOKUP(F5,Rounds!H$2:H$25,Rounds!E$2:E$25)) -> Curaçao | J5: Mexico | K5: =IFERROR(_xlfn.XLOOKUP(J5,Rounds!I$2:I$25,Rounds!J$2:J$25), _xlfn.XLOOKUP(J5,Rounds!L$2:L$25,Rounds!K$2:K$25)) -> 3 | L5: =IFERROR(_xlfn.XLOOKUP(J5,Rounds!I$2:I$25,Rounds!K$2:K$25), _xlfn.XLOOKUP(J5,Rounds!L$2:L$25,Rounds!J$2:J$25)) -> 0 | M5: =IFERROR(_xlfn.XLOOKUP(J5,Rounds!I$2:I$25,Rounds!L$2:L$25), _xlfn.XLOOKUP(J5,Rounds!L$2:L$25,Rounds!I$2:I$25)) -> Czech Republic | N5: Belgium | O5: =IFERROR(_xlfn.XLOOKUP(N5,Rounds!M$2:M$17,Rounds!N$2:N$17), _xlfn.XLOOKUP(N5,Rounds!P$2:P$17,Rounds!O$2:O$17)) -> 3 | P5: =IFERROR(_xlfn.XLOOKUP(N5,Rounds!M$2:M$17,Rounds!O$2:O$17), _xlfn.XLOOKUP(N5,Rounds!P$2:P$17,Rounds!N$2:N$17)) -> 2 | Q5: =IFERROR(_xlfn.XLOOKUP(N5,Rounds!M$2:M$17,Rounds!P$2:P$17), _xlfn.XLOOKUP(N5,Rounds!P$2:P$17,Rounds!M$2:M$17)) -> Senegal | R5: Morocco | S5: =IFERROR(_xlfn.XLOOKUP(R5,Rounds!Q$2:Q$9,Rounds!R$2:R$9), _xlfn.XLOOKUP(R5,Rounds!T$2:T$9,Rounds!S$2:S$9)) -> 3 | T5: =IFERROR(_xlfn.XLOOKUP(R5,Rounds!Q$2:Q$9,Rounds!S$2:S$9), _xlfn.XLOOKUP(R5,Rounds!T$2:T$9,Rounds!R$2:R$9)) -> 0 | U5: =IFERROR(_xlfn.XLOOKUP(R5,Rounds!Q$2:Q$9,Rounds!T$2:T$9), _xlfn.XLOOKUP(R5,Rounds!T$2:T$9,Rounds!Q$2:Q$9)) -> Canada | W5: =IFERROR(_xlfn.XLOOKUP(V5,Rounds!U$2:U$5,Rounds!V$2:V$5), _xlfn.XLOOKUP(V5,Rounds!X$2:X$5,Rounds!W$2:W$5)) -> #N/A | X5: =IFERROR(_xlfn.XLOOKUP(V5,Rounds!U$2:U$5,Rounds!W$2:W$5), _xlfn.XLOOKUP(V5,Rounds!X$2:X$5,Rounds!V$2:V$5)) -> #N/A | Y5: =IFERROR(_xlfn.XLOOKUP(V5,Rounds!U$2:U$5,Rounds!X$2:X$5), _xlfn.XLOOKUP(V5,Rounds!X$2:X$5,Rounds!U$2:U$5)) -> #N/A | AA5: =IFERROR(_xlfn.XLOOKUP(Z5,Rounds!Y$2:Y$3,Rounds!Z$2:Z$3), _xlfn.XLOOKUP(Z5,Rounds!AB$2:AB$3,Rounds!AA$2:AA$3)) -> #N/A | AB5: =IFERROR(_xlfn.XLOOKUP(Z5,Rounds!Y$2:Y$3,Rounds!AA$2:AA$3), _xlfn.XLOOKUP(Z5,Rounds!AB$2:AB$3,Rounds!Z$2:Z$3)) -> #N/A | AC5: =IFERROR(_xlfn.XLOOKUP(Z5,Rounds!Y$2:Y$3,Rounds!AB$2:AB$3), _xlfn.XLOOKUP(Z5,Rounds!AB$2:AB$3,Rounds!Y$2:Y$3)) -> #N/A | AE5: {=IFERROR(_xlfn.XLOOKUP(AD5,Rounds!AC$2:AC$2,Rounds!AD$2:AD$2), _xlfn.XLOOKUP(AD5,Rounds!AF$2:AF$2,Rounds!AE$2:AE$2))} -> #N/A | AF5: {=IFERROR(_xlfn.XLOOKUP(AD5,Rounds!AC$2:AC$2,Rounds!AE$2:AE$2), _xlfn.XLOOKUP(AD5,Rounds!AF$2:AF$2,Rounds!AD$2:AD$2))} -> #N/A | AG5: {=IFERROR(_xlfn.XLOOKUP(AD5,Rounds!AC$2:AC$2,Rounds!AF$2:AF$2), _xlfn.XLOOKUP(AD5,Rounds!AF$2:AF$2,Rounds!AC$2:AC$2))} -> #N/A
A6: Thomas | B6: Norway | C6: =IFERROR(_xlfn.XLOOKUP(B6,Rounds!A$2:A$25,Rounds!B$2:B$25), _xlfn.XLOOKUP(B6,Rounds!D$2:D$25,Rounds!C$2:C$25)) -> 4 | D6: =IFERROR(_xlfn.XLOOKUP(B6,Rounds!A$2:A$25,Rounds!C$2:C$25), _xlfn.XLOOKUP(B6,Rounds!D$2:D$25,Rounds!B$2:B$25)) -> 1 | E6: =IFERROR(_xlfn.XLOOKUP(B6,Rounds!A$2:A$25,Rounds!D$2:D$25), _xlfn.XLOOKUP(B6,Rounds!D$2:D$25,Rounds!A$2:A$25)) -> Iraq | F6: Japan | G6: =IFERROR(_xlfn.XLOOKUP(F6,Rounds!E$2:E$25,Rounds!F$2:F$25), _xlfn.XLOOKUP(F6,Rounds!H$2:H$25,Rounds!G$2:G$25)) -> 4 | H6: =IFERROR(_xlfn.XLOOKUP(F6,Rounds!E$2:E$25,Rounds!G$2:G$25), _xlfn.XLOOKUP(F6,Rounds!H$2:H$25,Rounds!F$2:F$25)) -> 0 | I6: =IFERROR(_xlfn.XLOOKUP(F6,Rounds!E$2:E$25,Rounds!H$2:H$25), _xlfn.XLOOKUP(F6,Rounds!H$2:H$25,Rounds!E$2:E$25)) -> Tunisia | J6: Ivory Coast | K6: =IFERROR(_xlfn.XLOOKUP(J6,Rounds!I$2:I$25,Rounds!J$2:J$25), _xlfn.XLOOKUP(J6,Rounds!L$2:L$25,Rounds!K$2:K$25)) -> 2 | L6: =IFERROR(_xlfn.XLOOKUP(J6,Rounds!I$2:I$25,Rounds!K$2:K$25), _xlfn.XLOOKUP(J6,Rounds!L$2:L$25,Rounds!J$2:J$25)) -> 0 | M6: =IFERROR(_xlfn.XLOOKUP(J6,Rounds!I$2:I$25,Rounds!L$2:L$25), _xlfn.XLOOKUP(J6,Rounds!L$2:L$25,Rounds!I$2:I$25)) -> Curaçao | N6: Germany | O6: =IFERROR(_xlfn.XLOOKUP(N6,Rounds!M$2:M$17,Rounds!N$2:N$17), _xlfn.XLOOKUP(N6,Rounds!P$2:P$17,Rounds!O$2:O$17)) -> 1 | P6: =IFERROR(_xlfn.XLOOKUP(N6,Rounds!M$2:M$17,Rounds!O$2:O$17), _xlfn.XLOOKUP(N6,Rounds!P$2:P$17,Rounds!N$2:N$17)) -> 2 | Q6: =IFERROR(_xlfn.XLOOKUP(N6,Rounds!M$2:M$17,Rounds!P$2:P$17), _xlfn.XLOOKUP(N6,Rounds!P$2:P$17,Rounds!M$2:M$17)) -> Paraguay | R6: Mexico | S6: =IFERROR(_xlfn.XLOOKUP(R6,Rounds!Q$2:Q$9,Rounds!R$2:R$9), _xlfn.XLOOKUP(R6,Rounds!T$2:T$9,Rounds!S$2:S$9)) -> 2 | T6: =IFERROR(_xlfn.XLOOKUP(R6,Rounds!Q$2:Q$9,Rounds!S$2:S$9), _xlfn.XLOOKUP(R6,Rounds!T$2:T$9,Rounds!R$2:R$9)) -> 3 | U6: =IFERROR(_xlfn.XLOOKUP(R6,Rounds!Q$2:Q$9,Rounds!T$2:T$9), _xlfn.XLOOKUP(R6,Rounds!T$2:T$9,Rounds!Q$2:Q$9)) -> England | W6: =IFERROR(_xlfn.XLOOKUP(V6,Rounds!U$2:U$5,Rounds!V$2:V$5), _xlfn.XLOOKUP(V6,Rounds!X$2:X$5,Rounds!W$2:W$5)) -> #N/A | X6: =IFERROR(_xlfn.XLOOKUP(V6,Rounds!U$2:U$5,Rounds!W$2:W$5), _xlfn.XLOOKUP(V6,Rounds!X$2:X$5,Rounds!V$2:V$5)) -> #N/A | Y6: =IFERROR(_xlfn.XLOOKUP(V6,Rounds!U$2:U$5,Rounds!X$2:X$5), _xlfn.XLOOKUP(V6,Rounds!X$2:X$5,Rounds!U$2:U$5)) -> #N/A | AA6: =IFERROR(_xlfn.XLOOKUP(Z6,Rounds!Y$2:Y$3,Rounds!Z$2:Z$3), _xlfn.XLOOKUP(Z6,Rounds!AB$2:AB$3,Rounds!AA$2:AA$3)) -> #N/A | AB6: =IFERROR(_xlfn.XLOOKUP(Z6,Rounds!Y$2:Y$3,Rounds!AA$2:AA$3), _xlfn.XLOOKUP(Z6,Rounds!AB$2:AB$3,Rounds!Z$2:Z$3)) -> #N/A | AC6: =IFERROR(_xlfn.XLOOKUP(Z6,Rounds!Y$2:Y$3,Rounds!AB$2:AB$3), _xlfn.XLOOKUP(Z6,Rounds!AB$2:AB$3,Rounds!Y$2:Y$3)) -> #N/A | AE6: {=IFERROR(_xlfn.XLOOKUP(AD6,Rounds!AC$2:AC$2,Rounds!AD$2:AD$2), _xlfn.XLOOKUP(AD6,Rounds!AF$2:AF$2,Rounds!AE$2:AE$2))} -> #N/A | AF6: {=IFERROR(_xlfn.XLOOKUP(AD6,Rounds!AC$2:AC$2,Rounds!AE$2:AE$2), _xlfn.XLOOKUP(AD6,Rounds!AF$2:AF$2,Rounds!AD$2:AD$2))} -> #N/A | AG6: {=IFERROR(_xlfn.XLOOKUP(AD6,Rounds!AC$2:AC$2,Rounds!AF$2:AF$2), _xlfn.XLOOKUP(AD6,Rounds!AF$2:AF$2,Rounds!AC$2:AC$2))} -> #N/A
A7: Heather | B7: Switzerland | C7: =IFERROR(_xlfn.XLOOKUP(B7,Rounds!A$2:A$25,Rounds!B$2:B$25), _xlfn.XLOOKUP(B7,Rounds!D$2:D$25,Rounds!C$2:C$25)) -> 1 | D7: =IFERROR(_xlfn.XLOOKUP(B7,Rounds!A$2:A$25,Rounds!C$2:C$25), _xlfn.XLOOKUP(B7,Rounds!D$2:D$25,Rounds!B$2:B$25)) -> 1 | E7: =IFERROR(_xlfn.XLOOKUP(B7,Rounds!A$2:A$25,Rounds!D$2:D$25), _xlfn.XLOOKUP(B7,Rounds!D$2:D$25,Rounds!A$2:A$25)) -> Qatar | F7: Egypt | G7: =IFERROR(_xlfn.XLOOKUP(F7,Rounds!E$2:E$25,Rounds!F$2:F$25), _xlfn.XLOOKUP(F7,Rounds!H$2:H$25,Rounds!G$2:G$25)) -> 3 | H7: =IFERROR(_xlfn.XLOOKUP(F7,Rounds!E$2:E$25,Rounds!G$2:G$25), _xlfn.XLOOKUP(F7,Rounds!H$2:H$25,Rounds!F$2:F$25)) -> 1 | I7: =IFERROR(_xlfn.XLOOKUP(F7,Rounds!E$2:E$25,Rounds!H$2:H$25), _xlfn.XLOOKUP(F7,Rounds!H$2:H$25,Rounds!E$2:E$25)) -> New Zealand | J7: Bosnia and Herzegovina | K7: =IFERROR(_xlfn.XLOOKUP(J7,Rounds!I$2:I$25,Rounds!J$2:J$25), _xlfn.XLOOKUP(J7,Rounds!L$2:L$25,Rounds!K$2:K$25)) -> 3 | L7: =IFERROR(_xlfn.XLOOKUP(J7,Rounds!I$2:I$25,Rounds!K$2:K$25), _xlfn.XLOOKUP(J7,Rounds!L$2:L$25,Rounds!J$2:J$25)) -> 1 | M7: =IFERROR(_xlfn.XLOOKUP(J7,Rounds!I$2:I$25,Rounds!L$2:L$25), _xlfn.XLOOKUP(J7,Rounds!L$2:L$25,Rounds!I$2:I$25)) -> Qatar | N7: Belgium | O7: =IFERROR(_xlfn.XLOOKUP(N7,Rounds!M$2:M$17,Rounds!N$2:N$17), _xlfn.XLOOKUP(N7,Rounds!P$2:P$17,Rounds!O$2:O$17)) -> 3 | P7: =IFERROR(_xlfn.XLOOKUP(N7,Rounds!M$2:M$17,Rounds!O$2:O$17), _xlfn.XLOOKUP(N7,Rounds!P$2:P$17,Rounds!N$2:N$17)) -> 2 | Q7: =IFERROR(_xlfn.XLOOKUP(N7,Rounds!M$2:M$17,Rounds!P$2:P$17), _xlfn.XLOOKUP(N7,Rounds!P$2:P$17,Rounds!M$2:M$17)) -> Senegal | R7: Spain | S7: =IFERROR(_xlfn.XLOOKUP(R7,Rounds!Q$2:Q$9,Rounds!R$2:R$9), _xlfn.XLOOKUP(R7,Rounds!T$2:T$9,Rounds!S$2:S$9)) -> 1 | T7: =IFERROR(_xlfn.XLOOKUP(R7,Rounds!Q$2:Q$9,Rounds!S$2:S$9), _xlfn.XLOOKUP(R7,Rounds!T$2:T$9,Rounds!R$2:R$9)) -> 0 | U7: =IFERROR(_xlfn.XLOOKUP(R7,Rounds!Q$2:Q$9,Rounds!T$2:T$9), _xlfn.XLOOKUP(R7,Rounds!T$2:T$9,Rounds!Q$2:Q$9)) -> Portugal | W7: =IFERROR(_xlfn.XLOOKUP(V7,Rounds!U$2:U$5,Rounds!V$2:V$5), _xlfn.XLOOKUP(V7,Rounds!X$2:X$5,Rounds!W$2:W$5)) -> #N/A | X7: =IFERROR(_xlfn.XLOOKUP(V7,Rounds!U$2:U$5,Rounds!W$2:W$5), _xlfn.XLOOKUP(V7,Rounds!X$2:X$5,Rounds!V$2:V$5)) -> #N/A | Y7: =IFERROR(_xlfn.XLOOKUP(V7,Rounds!U$2:U$5,Rounds!X$2:X$5), _xlfn.XLOOKUP(V7,Rounds!X$2:X$5,Rounds!U$2:U$5)) -> #N/A | AA7: =IFERROR(_xlfn.XLOOKUP(Z7,Rounds!Y$2:Y$3,Rounds!Z$2:Z$3), _xlfn.XLOOKUP(Z7,Rounds!AB$2:AB$3,Rounds!AA$2:AA$3)) -> #N/A | AB7: =IFERROR(_xlfn.XLOOKUP(Z7,Rounds!Y$2:Y$3,Rounds!AA$2:AA$3), _xlfn.XLOOKUP(Z7,Rounds!AB$2:AB$3,Rounds!Z$2:Z$3)) -> #N/A | AC7: =IFERROR(_xlfn.XLOOKUP(Z7,Rounds!Y$2:Y$3,Rounds!AB$2:AB$3), _xlfn.XLOOKUP(Z7,Rounds!AB$2:AB$3,Rounds!Y$2:Y$3)) -> #N/A | AE7: {=IFERROR(_xlfn.XLOOKUP(AD7,Rounds!AC$2:AC$2,Rounds!AD$2:AD$2), _xlfn.XLOOKUP(AD7,Rounds!AF$2:AF$2,Rounds!AE$2:AE$2))} -> #N/A | AF7: {=IFERROR(_xlfn.XLOOKUP(AD7,Rounds!AC$2:AC$2,Rounds!AE$2:AE$2), _xlfn.XLOOKUP(AD7,Rounds!AF$2:AF$2,Rounds!AD$2:AD$2))} -> #N/A | AG7: {=IFERROR(_xlfn.XLOOKUP(AD7,Rounds!AC$2:AC$2,Rounds!AF$2:AF$2), _xlfn.XLOOKUP(AD7,Rounds!AF$2:AF$2,Rounds!AC$2:AC$2))} -> #N/A
A8: Joey | B8: Switzerland | C8: =IFERROR(_xlfn.XLOOKUP(B8,Rounds!A$2:A$25,Rounds!B$2:B$25), _xlfn.XLOOKUP(B8,Rounds!D$2:D$25,Rounds!C$2:C$25)) -> 1 | D8: =IFERROR(_xlfn.XLOOKUP(B8,Rounds!A$2:A$25,Rounds!C$2:C$25), _xlfn.XLOOKUP(B8,Rounds!D$2:D$25,Rounds!B$2:B$25)) -> 1 | E8: =IFERROR(_xlfn.XLOOKUP(B8,Rounds!A$2:A$25,Rounds!D$2:D$25), _xlfn.XLOOKUP(B8,Rounds!D$2:D$25,Rounds!A$2:A$25)) -> Qatar | F8: Ecuador | G8: =IFERROR(_xlfn.XLOOKUP(F8,Rounds!E$2:E$25,Rounds!F$2:F$25), _xlfn.XLOOKUP(F8,Rounds!H$2:H$25,Rounds!G$2:G$25)) -> 0 | H8: =IFERROR(_xlfn.XLOOKUP(F8,Rounds!E$2:E$25,Rounds!G$2:G$25), _xlfn.XLOOKUP(F8,Rounds!H$2:H$25,Rounds!F$2:F$25)) -> 0 | I8: =IFERROR(_xlfn.XLOOKUP(F8,Rounds!E$2:E$25,Rounds!H$2:H$25), _xlfn.XLOOKUP(F8,Rounds!H$2:H$25,Rounds!E$2:E$25)) -> Curaçao | J8: Morocco | K8: =IFERROR(_xlfn.XLOOKUP(J8,Rounds!I$2:I$25,Rounds!J$2:J$25), _xlfn.XLOOKUP(J8,Rounds!L$2:L$25,Rounds!K$2:K$25)) -> 4 | L8: =IFERROR(_xlfn.XLOOKUP(J8,Rounds!I$2:I$25,Rounds!K$2:K$25), _xlfn.XLOOKUP(J8,Rounds!L$2:L$25,Rounds!J$2:J$25)) -> 2 | M8: =IFERROR(_xlfn.XLOOKUP(J8,Rounds!I$2:I$25,Rounds!L$2:L$25), _xlfn.XLOOKUP(J8,Rounds!L$2:L$25,Rounds!I$2:I$25)) -> Haiti | N8: Canada | O8: =IFERROR(_xlfn.XLOOKUP(N8,Rounds!M$2:M$17,Rounds!N$2:N$17), _xlfn.XLOOKUP(N8,Rounds!P$2:P$17,Rounds!O$2:O$17)) -> 1 | P8: =IFERROR(_xlfn.XLOOKUP(N8,Rounds!M$2:M$17,Rounds!O$2:O$17), _xlfn.XLOOKUP(N8,Rounds!P$2:P$17,Rounds!N$2:N$17)) -> 0 | Q8: =IFERROR(_xlfn.XLOOKUP(N8,Rounds!M$2:M$17,Rounds!P$2:P$17), _xlfn.XLOOKUP(N8,Rounds!P$2:P$17,Rounds!M$2:M$17)) -> South Africa | R8: England | S8: =IFERROR(_xlfn.XLOOKUP(R8,Rounds!Q$2:Q$9,Rounds!R$2:R$9), _xlfn.XLOOKUP(R8,Rounds!T$2:T$9,Rounds!S$2:S$9)) -> 3 | T8: =IFERROR(_xlfn.XLOOKUP(R8,Rounds!Q$2:Q$9,Rounds!S$2:S$9), _xlfn.XLOOKUP(R8,Rounds!T$2:T$9,Rounds!R$2:R$9)) -> 2 | U8: =IFERROR(_xlfn.XLOOKUP(R8,Rounds!Q$2:Q$9,Rounds!T$2:T$9), _xlfn.XLOOKUP(R8,Rounds!T$2:T$9,Rounds!Q$2:Q$9)) -> Mexico | W8: =IFERROR(_xlfn.XLOOKUP(V8,Rounds!U$2:U$5,Rounds!V$2:V$5), _xlfn.XLOOKUP(V8,Rounds!X$2:X$5,Rounds!W$2:W$5)) -> #N/A | X8: =IFERROR(_xlfn.XLOOKUP(V8,Rounds!U$2:U$5,Rounds!W$2:W$5), _xlfn.XLOOKUP(V8,Rounds!X$2:X$5,Rounds!V$2:V$5)) -> #N/A | Y8: =IFERROR(_xlfn.XLOOKUP(V8,Rounds!U$2:U$5,Rounds!X$2:X$5), _xlfn.XLOOKUP(V8,Rounds!X$2:X$5,Rounds!U$2:U$5)) -> #N/A | AA8: =IFERROR(_xlfn.XLOOKUP(Z8,Rounds!Y$2:Y$3,Rounds!Z$2:Z$3), _xlfn.XLOOKUP(Z8,Rounds!AB$2:AB$3,Rounds!AA$2:AA$3)) -> #N/A | AB8: =IFERROR(_xlfn.XLOOKUP(Z8,Rounds!Y$2:Y$3,Rounds!AA$2:AA$3), _xlfn.XLOOKUP(Z8,Rounds!AB$2:AB$3,Rounds!Z$2:Z$3)) -> #N/A | AC8: =IFERROR(_xlfn.XLOOKUP(Z8,Rounds!Y$2:Y$3,Rounds!AB$2:AB$3), _xlfn.XLOOKUP(Z8,Rounds!AB$2:AB$3,Rounds!Y$2:Y$3)) -> #N/A | AE8: {=IFERROR(_xlfn.XLOOKUP(AD8,Rounds!AC$2:AC$2,Rounds!AD$2:AD$2), _xlfn.XLOOKUP(AD8,Rounds!AF$2:AF$2,Rounds!AE$2:AE$2))} -> #N/A | AF8: {=IFERROR(_xlfn.XLOOKUP(AD8,Rounds!AC$2:AC$2,Rounds!AE$2:AE$2), _xlfn.XLOOKUP(AD8,Rounds!AF$2:AF$2,Rounds!AD$2:AD$2))} -> #N/A | AG8: {=IFERROR(_xlfn.XLOOKUP(AD8,Rounds!AC$2:AC$2,Rounds!AF$2:AF$2), _xlfn.XLOOKUP(AD8,Rounds!AF$2:AF$2,Rounds!AC$2:AC$2))} -> #N/A

Sheet Rounds
A1: Round 1 | E1: Round 2 | I1: Round 3 | M1: Round 4 | Q1: Round 5 | U1: Round 6 | Y1: Round 7 | AC1: Round 8
A2: {=IF('2026 World Cup'!E7:H30="",NA(),'2026 World Cup'!E7:H30)} -> Mexico | B2: 2 | C2: 0 | D2: South Africa | E2: {=IF('2026 World Cup'!E31:H54="",NA(),'2026 World Cup'!E31:H54)} -> Czech Republic | F2: 1 | G2: 1 | H2: South Africa | I2: {=IF('2026 World Cup'!E55:H78="",NA(),'2026 World Cup'!E55:H78)} -> Scotland | J2: 0 | K2: 3 | L2: Brazil | M2: =IF('2026 World Cup'!BL10="",NA(),'2026 World Cup'!BL10) -> Germany | N2: =IF('2026 World Cup'!$BM10="",NA(),'2026 World Cup'!$BM10) -> 1 | O2: =IF('2026 World Cup'!$BM11="",NA(),'2026 World Cup'!$BM11) -> 2 | P2: ='2026 World Cup'!BL11 -> Paraguay | Q2: ='2026 World Cup'!BS12 -> Paraguay | R2: =IF('2026 World Cup'!$BT12="",NA(),'2026 World Cup'!$BT12) -> 0 | S2: =IF('2026 World Cup'!$BT13="",NA(),'2026 World Cup'!$BT13) -> 1 | T2: ='2026 World Cup'!BS13 -> France | U2: ='2026 World Cup'!BZ16 -> France | V2: =IF('2026 World Cup'!$CA16="",NA(),'2026 World Cup'!$CA16) -> #N/A | W2: =IF('2026 World Cup'!$CA17="",NA(),'2026 World Cup'!$CA17) -> #N/A | X2: ='2026 World Cup'!BZ17 -> Morocco | Y2: ='2026 World Cup'!CG23 | Z2: =IF('2026 World Cup'!$CH23="",NA(),'2026 World Cup'!$CH23) -> #N/A | AA2: =IF('2026 World Cup'!$CH24="",NA(),'2026 World Cup'!$CH24) -> #N/A | AB2: ='2026 World Cup'!CG24 | AC2: ='2026 World Cup'!CN37 | AD2: =IF('2026 World Cup'!$CO37="",NA(),'2026 World Cup'!$CO37) -> #N/A | AE2: =IF('2026 World Cup'!$CO38="",NA(),'2026 World Cup'!$CO38) -> #N/A | AF2: ='2026 World Cup'!CN38
A3: Korea Republic | B3: 2 | C3: 1 | D3: Czech Republic | E3: Switzerland | F3: 4 | G3: 1 | H3: Bosnia and Herzegovina | I3: Morocco | J3: 4 | K3: 2 | L3: Haiti | M3: ='2026 World Cup'!BL14 -> France | N3: =IF('2026 World Cup'!$BM14="",NA(),'2026 World Cup'!$BM14) -> 3 | O3: =IF('2026 World Cup'!$BM15="",NA(),'2026 World Cup'!$BM15) -> 0 | P3: ='2026 World Cup'!BL15 -> Sweden | Q3: ='2026 World Cup'!BS20 -> Canada | R3: =IF('2026 World Cup'!$BT20="",NA(),'2026 World Cup'!$BT20) -> 0 | S3: =IF('2026 World Cup'!$BT21="",NA(),'2026 World Cup'!$BT21) -> 3 | T3: ='2026 World Cup'!BS21 -> Morocco | U3: ='2026 World Cup'!BZ32 -> Spain | V3: =IF('2026 World Cup'!$CA32="",NA(),'2026 World Cup'!$CA32) -> #N/A | W3: =IF('2026 World Cup'!$CA33="",NA(),'2026 World Cup'!$CA33) -> #N/A | X3: ='2026 World Cup'!BZ33 | Y3: ='2026 World Cup'!CG55 | Z3: =IF('2026 World Cup'!$CH55="",NA(),'2026 World Cup'!$CH55) -> #N/A | AA3: =IF('2026 World Cup'!$CH56="",NA(),'2026 World Cup'!$CH56) -> #N/A | AB3: ='2026 World Cup'!CG56
A4: Canada | B4: 1 | C4: 1 | D4: Bosnia and Herzegovina | E4: Canada | F4: 6 | G4: 0 | H4: Qatar | I4: Switzerland | J4: 2 | K4: 1 | L4: Canada | M4: ='2026 World Cup'!BL18 -> South Africa | N4: =IF('2026 World Cup'!$BM18="",NA(),'2026 World Cup'!$BM18) -> 0 | O4: =IF('2026 World Cup'!$BM19="",NA(),'2026 World Cup'!$BM19) -> 1 | P4: ='2026 World Cup'!BL19 -> Canada | Q4: ='2026 World Cup'!BS28 -> Portugal | R4: =IF('2026 World Cup'!$BT28="",NA(),'2026 World Cup'!$BT28) -> 0 | S4: =IF('2026 World Cup'!$BT29="",NA(),'2026 World Cup'!$BT29) -> 1 | T4: ='2026 World Cup'!BS29 -> Spain | U4: ='2026 World Cup'!BZ48 -> Norway | V4: =IF('2026 World Cup'!$CA48="",NA(),'2026 World Cup'!$CA48) -> #N/A | W4: =IF('2026 World Cup'!$CA49="",NA(),'2026 World Cup'!$CA49) -> #N/A | X4: ='2026 World Cup'!BZ49 -> England
A5: United States | B5: 4 | C5: 1 | D5: Paraguay | E5: Mexico | F5: 1 | G5: 0 | H5: Korea Republic | I5: Bosnia and Herzegovina | J5: 3 | K5: 1 | L5: Qatar | M5: ='2026 World Cup'!BL22 -> Netherlands | N5: =IF('2026 World Cup'!$BM22="",NA(),'2026 World Cup'!$BM22) -> 1 | O5: =IF('2026 World Cup'!$BM23="",NA(),'2026 World Cup'!$BM23) -> 2 | P5: ='2026 World Cup'!BL23 -> Morocco | Q5: ='2026 World Cup'!BS36 -> United States | R5: =IF('2026 World Cup'!$BT36="",NA(),'2026 World Cup'!$BT36) -> #N/A | S5: =IF('2026 World Cup'!$BT37="",NA(),'2026 World Cup'!$BT37) -> #N/A | T5: ='2026 World Cup'!BS37 -> Belgium | U5: ='2026 World Cup'!BZ64 | V5: =IF('2026 World Cup'!$CA64="",NA(),'2026 World Cup'!$CA64) -> #N/A | W5: =IF('2026 World Cup'!$CA65="",NA(),'2026 World Cup'!$CA65) -> #N/A | X5: ='2026 World Cup'!BZ65
A6: Haiti | B6: 0 | C6: 1 | D6: Scotland | E6: Brazil | F6: 3 | G6: 0 | H6: Haiti | I6: Czech Republic | J6: 0 | K6: 3 | L6: Mexico | M6: ='2026 World Cup'!BL26 -> Portugal | N6: =IF('2026 World Cup'!$BM26="",NA(),'2026 World Cup'!$BM26) -> 2 | O6: =IF('2026 World Cup'!$BM27="",NA(),'2026 World Cup'!$BM27) -> 1 | P6: ='2026 World Cup'!BL27 -> Croatia | Q6: ='2026 World Cup'!BS44 -> Brazil | R6: =IF('2026 World Cup'!$BT44="",NA(),'2026 World Cup'!$BT44) -> 1 | S6: =IF('2026 World Cup'!$BT45="",NA(),'2026 World Cup'!$BT45) -> 2 | T6: ='2026 World Cup'!BS45 -> Norway
A7: Australia | B7: 2 | C7: 0 | D7: Turkey | E7: Scotland | F7: 0 | G7: 1 | H7: Morocco | I7: South Africa | J7: 1 | K7: 0 | L7: Korea Republic | M7: ='2026 World Cup'!BL30 -> Spain | N7: =IF('2026 World Cup'!$BM30="",NA(),'2026 World Cup'!$BM30) -> 3 | O7: =IF('2026 World Cup'!$BM31="",NA(),'2026 World Cup'!$BM31) -> 0 | P7: ='2026 World Cup'!BL31 -> Austria | Q7: ='2026 World Cup'!BS52 -> Mexico | R7: =IF('2026 World Cup'!$BT52="",NA(),'2026 World Cup'!$BT52) -> 2 | S7: =IF('2026 World Cup'!$BT53="",NA(),'2026 World Cup'!$BT53) -> 3 | T7: ='2026 World Cup'!BS53 -> England
A8: Brazil | B8: 1 | C8: 1 | D8: Morocco | E8: United States | F8: 2 | G8: 0 | H8: Australia | I8: Curaçao | J8: 0 | K8: 2 | L8: Ivory Coast | M8: ='2026 World Cup'!BL34 -> United States | N8: =IF('2026 World Cup'!$BM34="",NA(),'2026 World Cup'!$BM34) -> 2 | O8: =IF('2026 World Cup'!$BM35="",NA(),'2026 World Cup'!$BM35) -> 0 | P8: ='2026 World Cup'!BL35 -> Bosnia and Herzegovina | Q8: ='2026 World Cup'!BS60 -> Argentina | R8: =IF('2026 World Cup'!$BT60="",NA(),'2026 World Cup'!$BT60) -> #N/A | S8: =IF('2026 World Cup'!$BT61="",NA(),'2026 World Cup'!$BT61) -> #N/A | T8: ='2026 World Cup'!BS61 -> Egypt
A9: Qatar | B9: 1 | C9: 1 | D9: Switzerland | E9: Turkey | F9: 0 | G9: 1 | H9: Paraguay | I9: Ecuador | J9: 2 | K9: 1 | L9: Germany | M9: ='2026 World Cup'!BL38 -> Belgium | N9: =IF('2026 World Cup'!$BM38="",NA(),'2026 World Cup'!$BM38) -> 3 | O9: =IF('2026 World Cup'!$BM39="",NA(),'2026 World Cup'!$BM39) -> 2 | P9: ='2026 World Cup'!BL39 -> Senegal | Q9: ='2026 World Cup'!BS68 -> Switzerland | R9: =IF('2026 World Cup'!$BT68="",NA(),'2026 World Cup'!$BT68) -> #N/A | S9: =IF('2026 World Cup'!$BT69="",NA(),'2026 World Cup'!$BT69) -> #N/A | T9: ='2026 World Cup'!BS69 -> Colombia
A10: Ivory Coast | B10: 1 | C10: 0 | D10: Ecuador | E10: Germany | F10: 2 | G10: 1 | H10: Ivory Coast | I10: Japan | J10: 1 | K10: 1 | L10: Sweden | M10: ='2026 World Cup'!BL42 -> Brazil | N10: =IF('2026 World Cup'!$BM42="",NA(),'2026 World Cup'!$BM42) -> 2 | O10: =IF('2026 World Cup'!$BM43="",NA(),'2026 World Cup'!$BM43) -> 1 | P10: ='2026 World Cup'!BL43 -> Japan
A11: Germany | B11: 7 | C11: 1 | D11: Curaçao | E11: Ecuador | F11: 0 | G11: 0 | H11: Curaçao | I11: Tunisia | J11: 1 | K11: 3 | L11: Netherlands | M11: ='2026 World Cup'!BL46 -> Ivory Coast | N11: =IF('2026 World Cup'!$BM46="",NA(),'2026 World Cup'!$BM46) -> 1 | O11: =IF('2026 World Cup'!$BM47="",NA(),'2026 World Cup'!$BM47) -> 2 | P11: ='2026 World Cup'!BL47 -> Norway
A12: Netherlands | B12: 2 | C12: 2 | D12: Japan | E12: Netherlands | F12: 5 | G12: 1 | H12: Sweden | I12: Turkey | J12: 3 | K12: 2 | L12: United States | M12: ='2026 World Cup'!BL50 -> Mexico | N12: =IF('2026 World Cup'!$BM50="",NA(),'2026 World Cup'!$BM50) -> 2 | O12: =IF('2026 World Cup'!$BM51="",NA(),'2026 World Cup'!$BM51) -> 0 | P12: ='2026 World Cup'!BL51 -> Ecuador
A13: Sweden | B13: 5 | C13: 1 | D13: Tunisia | E13: Tunisia | F13: 0 | G13: 4 | H13: Japan | I13: Paraguay | J13: 0 | K13: 0 | L13: Australia | M13: ='2026 World Cup'!BL54 -> England | N13: =IF('2026 World Cup'!$BM54="",NA(),'2026 World Cup'!$BM54) -> 2 | O13: =IF('2026 World Cup'!$BM55="",NA(),'2026 World Cup'!$BM55) -> 1 | P13: ='2026 World Cup'!BL55 -> DR Congo
A14: Saudi Arabia | B14: 1 | C14: 1 | D14: Uruguay | E14: Uruguay | F14: 2 | G14: 2 | H14: Cape Verde | I14: Norway | J14: 1 | K14: 4 | L14: France | M14: ='2026 World Cup'!BL58 -> Argentina | N14: =IF('2026 World Cup'!$BM58="",NA(),'2026 World Cup'!$BM58) -> 3 | O14: =IF('2026 World Cup'!$BM59="",NA(),'2026 World Cup'!$BM59) -> 2 | P14: ='2026 World Cup'!BL59 -> Cape Verde
A15: Spain | B15: 0 | C15: 0 | D15: Cape Verde | E15: Spain | F15: 4 | G15: 0 | H15: Saudi Arabia | I15: Senegal | J15: 5 | K15: 0 | L15: Iraq | M15: ='2026 World Cup'!BL62 -> Australia | N15: =IF('2026 World Cup'!$BM62="",NA(),'2026 World Cup'!$BM62) -> 1 | O15: =IF('2026 World Cup'!$BM63="",NA(),'2026 World Cup'!$BM63) -> 2 | P15: ='2026 World Cup'!BL63 -> Egypt
A16: Iran | B16: 2 | C16: 2 | D16: New Zealand | E16: Belgium | F16: 0 | G16: 0 | H16: Iran | I16: Egypt | J16: 1 | K16: 1 | L16: Iran | M16: ='2026 World Cup'!BL66 -> Switzerland | N16: =IF('2026 World Cup'!$BM66="",NA(),'2026 World Cup'!$BM66) -> 2 | O16: =IF('2026 World Cup'!$BM67="",NA(),'2026 World Cup'!$BM67) -> 0 | P16: ='2026 World Cup'!BL67 -> Algeria
A17: Belgium | B17: 1 | C17: 1 | D17: Egypt | E17: New Zealand | F17: 1 | G17: 3 | H17: Egypt | I17: New Zealand | J17: 1 | K17: 5 | L17: Belgium | M17: ='2026 World Cup'!BL70 -> Colombia | N17: =IF('2026 World Cup'!$BM70="",NA(),'2026 World Cup'!$BM70) -> 1 | O17: =IF('2026 World Cup'!$BM71="",NA(),'2026 World Cup'!$BM71) -> 0 | P17: ='2026 World Cup'!BL71 -> Ghana
A18: France | B18: 3 | C18: 1 | D18: Senegal | E18: Norway | F18: 3 | G18: 2 | H18: Senegal | I18: Cape Verde | J18: 0 | K18: 0 | L18: Saudi Arabia
A19: Iraq | B19: 1 | C19: 4 | D19: Norway | E19: France | F19: 3 | G19: 0 | H19: Iraq | I19: Uruguay | J19: 0 | K19: 1 | L19: Spain
A20: Argentina | B20: 3 | C20: 0 | D20: Algeria | E20: Argentina | F20: 2 | G20: 0 | H20: Austria | I20: Panama | J20: 0 | K20: 2 | L20: England
A21: Austria | B21: 3 | C21: 1 | D21: Jordan | E21: Jordan | F21: 1 | G21: 2 | H21: Algeria | I21: Croatia | J21: 2 | K21: 1 | L21: Ghana
A22: Ghana | B22: 1 | C22: 0 | D22: Panama | E22: England | F22: 0 | G22: 0 | H22: Ghana | I22: Algeria | J22: 3 | K22: 3 | L22: Austria
A23: England | B23: 4 | C23: 2 | D23: Croatia | E23: Panama | F23: 0 | G23: 1 | H23: Croatia | I23: Jordan | J23: 1 | K23: 3 | L23: Argentina
A24: Portugal | B24: 1 | C24: 1 | D24: DR Congo | E24: Portugal | F24: 5 | G24: 0 | H24: Uzbekistan | I24: Colombia | J24: 0 | K24: 0 | L24: Portugal
A25: Uzbekistan | B25: 1 | C25: 3 | D25: Colombia | E25: Colombia | F25: 1 | G25: 0 | H25: DR Congo | I25: DR Congo | J25: 3 | K25: 1 | L25: Uzbekistan

Sheet 2026 World Cup
A1: {=INDEX(T,2,lang)} -> 2026 World Cup Final Tournament Schedule
O3: ="Language: " & Settings!C4 -> Language: English
A5: {=INDEX(T,3,lang)} -> Group Stage | J5: Home Page: www.excely.com
R6: Date + Time + GMT | V6: GF | W6: GA | Y6: GF | Z6: GA | AA6: =IF(Settings!C14="Yes",INT(MATCH(my_team,$AE$8:$AE$78,0)/6),-1) -> -1 | AD6: Place | AE6: Team | AF6: W | AG6: D | AH6: L | AI6: GF | AJ6: GA | AL6: F-A | AM6: F-A (norm) | AN6: Pnt | AO6: R1 | AP6: R2 | AQ6: FIFA | AR6: Rank | AT6: W | AU6: D | AV6: GF | AW6: GA | AX6: F-A | AY6: F-A (norm) | AZ6: Rank | BA6: R (norm) | BB6: W | BC6: D | BD6: GF | BE6: GA | BF6: F-A | BG6: F-A (norm) | BH6: Rank | BI6: R (norm) | BK6: Round of 32 | BR6: {=INDEX(T,4,lang)} -> Round of 16 | BY6: {=INDEX(T,5,lang)} -> Quarterfinals | CF6: {=INDEX(T,6,lang)} -> Semi-Finals
A7: 1 | B7: {=INDEX(T,18+INT(MOD(R7-1,7)),lang)} -> Thu | C7: {=INDEX(T,24+MONTH(R7),lang) & " " & DAY(R7) & ", " & YEAR(R7)} -> Jun 11, 2026 | D7: =TIME(HOUR(R7),MINUTE(R7),0) -> 0.79166667 | E7: =AE8 -> Mexico | F7: 2 | G7: 0 | H7: =AE9 -> South Africa | R7: =DATE(2026,6,11)+TIME(8,0,0)+gmt_delta -> 46184.792 | S7: =IF(OR(F7="",G7=""),"",IF(F7>G7,E7&"_win",IF(F7<G7,E7&"_lose",E7&"_draw"))) -> Mexico_win | T7: =IF(S7="","",IF(F7<G7,H7&"_win",IF(F7>G7,H7&"_lose",H7&"_draw"))) -> South Africa_lose | U7: =IF(S7="",0,IF(VLOOKUP(E7,$AE$8:$AN$77,10,FALSE)=VLOOKUP(H7,$AE$8:$AN$77,10,FALSE),1,0)) -> 0 | V7: =U7*F7 -> 0 | W7: =U7*G7 -> 0 | X7: =IF(S7="",0,IF(VLOOKUP(E7,$AE$8:$AO$77,11,FALSE)=VLOOKUP(H7,$AE$8:$AO$77,11,FALSE),1,0)) -> 0 | Y7: =X7*F7 -> 0 | Z7: =X7*G7 -> 0 | AA7: =IF(OR(E7=my_team,H7=my_team),1,IF(INT(MATCH(E7,$AE$8:$AE$78,0)/6)=$AA$6,1,0)) -> 0 | AB7: =IF(OR(F7="",G7=""),"",IF(F7>G7,1,IF(F7<G7,-1,0))) -> 1
A8: 2 | B8: {=INDEX(T,18+INT(MOD(R8-1,7)),lang)} -> Fri | C8: {=INDEX(T,24+MONTH(R8),lang) & " " & DAY(R8) & ", " & YEAR(R8)} -> Jun 12, 2026 | D8: =TIME(HOUR(R8),MINUTE(R8),0) -> 0.083333333 | E8: =AE10 -> Korea Republic | F8: 2 | G8: 1 | H8: =AE11 -> Czech Republic | J8: {=INDEX(T,9,lang) & " " & "A"} -> Group A | K8: {=INDEX(T,10,lang)} -> PL | L8: {=INDEX(T,11,lang)} -> W | M8: {=INDEX(T,12,lang)} -> DRAW | N8: {=INDEX(T,13,lang)} -> L | O8: {=INDEX(T,14,lang)} -> GF - GA | P8: {=INDEX(T,15,lang)} -> PNT | R8: =DATE(2026,6,11)+TIME(15,0,0)+gmt_delta -> 46185.083 | S8: =IF(OR(F8="",G8=""),"",IF(F8>G8,E8&"_win",IF(F8<G8,E8&"_lose",E8&"_draw"))) -> Korea Republic_win | T8: =IF(S8="","",IF(F8<G8,H8&"_win",IF(F8>G8,H8&"_lose",H8&"_draw"))) -> Czech Republic_lose | U8: =IF(S8="",0,IF(VLOOKUP(E8,$AE$8:$AN$77,10,FALSE)=VLOOKUP(H8,$AE$8:$AN$77,10,FALSE),1,0)) -> 0 | V8: =U8*F8 -> 0 | W8: =U8*G8 -> 0 | X8: =IF(S8="",0,IF(VLOOKUP(E8,$AE$8:$AO$77,11,FALSE)=VLOOKUP(H8,$AE$8:$AO$77,11,FALSE),1,0)) -> 0 | Y8: =X8*F8 -> 0 | Z8: =X8*G8 -> 0 | AA8: =IF(OR(E8=my_team,H8=my_team),1,IF(INT(MATCH(E8,$AE$8:$AE$78,0)/6)=$AA$6,1,0)) -> 0 | AB8: =IF(OR(F8="",G8=""),"",IF(F8>G8,1,IF(F8<G8,-1,0))) -> 1 | AD8: =COUNTIF(AR8:AR11,CONCATENATE(">=",AR8)) -> 1 | AE8: =VLOOKUP("Mexico",T,lang,FALSE) -> Mexico | AF8: =COUNTIF($S$7:$T$78,"=" & AE8 & "_win") -> 3 | AG8: =COUNTIF($S$7:$T$78,"=" & AE8 & "_draw") -> 0 | AH8: =COUNTIF($S$7:$T$78,"=" & AE8 & "_lose") -> 0 | AI8: =SUMIF($E$7:$E$78,$AE8,$F$7:$F$78) + SUMIF($H$7:$H$78,$AE8,$G$7:$G$78) -> 6 | AJ8: =SUMIF($E$7:$E$78,$AE8,$G$7:$G$78) + SUMIF($H$7:$H$78,$AE8,$F$7:$F$78) -> 0 | AL8: =AI8-AJ8 -> 6 | AM8: =AL8-AL12 -> 10 | AN8: =AF8*3+AG8 -> 9 | AO8: =AN8/AN12*10+BA8 -> 9 | AP8: =AO8*10000000+BI8*100+AM8/AM12*10+AI8/AI12*1++IF(AQ8=0,ROW(),AQ8)/2000000 -> 90000010 | AQ8: =VLOOKUP(AE8,db_fifarank,2,FALSE) -> 1681.03 | AR8: =AP8/AP12 -> 0.99999999 | AS8: =IF(SUM(AF8:AH11)=12,J9,"1A") -> Mexico | AT8: {=SUMPRODUCT(($S$7:$S$78=AE8&"_win")*($U$7:$U$78))+SUMPRODUCT(($T$7:$T$78=AE8&"_win")*($U$7:$U$78))} -> 0 | AU8: {=SUMPRODUCT(($S$7:$S$78=AE8&"_draw")*($U$7:$U$78))+SUMPRODUCT(($T$7:$T$78=AE8&"_draw")*($U$7:$U$78))} -> 0 | AV8: {=SUMPRODUCT(($E$7:$E$78=AE8)*($U$7:$U$78)*($F$7:$F$78))+SUMPRODUCT(($H$7:$H$78=AE8)*($U$7:$U$78)*($G$7:$G$78))} -> 0 | AW8: {=SUMPRODUCT(($E$7:$E$78=AE8)*($U$7:$U$78)*($G$7:$G$78))+SUMPRODUCT(($H$7:$H$78=AE8)*($U$7:$U$78)*($F$7:$F$78))} -> 0 | AX8: =AV8-AW8 -> 0 | AY8: =AX8-MIN(AX8:AX11) -> 0 | AZ8: =AT8/AT12*1000+AU8/AU12*100+AY8/AY12*10+AV8/AV12 -> 0 | BA8: =AZ8/AZ12 -> 0 | BB8: {=SUMPRODUCT(($S$7:$S$78=AE8&"_win")*($X$7:$X$78))+SUMPRODUCT(($T$7:$T$78=AE8&"_win")*($X$7:$X$78))} -> 0 | BC8: {=SUMPRODUCT(($S$7:$S$78=AE8&"_draw")*($X$7:$X$78))+SUMPRODUCT(($T$7:$T$78=AE8&"_draw")*($X$7:$X$78))} -> 0 | BD8: {=SUMPRODUCT(($E$7:$E$78=AE8)*($X$7:$X$78)*($F$7:$F$78))+SUMPRODUCT(($H$7:$H$78=AE8)*($X$7:$X$78)*($G$7:$G$78))} -> 0 | BE8: {=SUMPRODUCT(($E$7:$E$78=AE8)*($X$7:$X$78)*($G$7:$G$78))+SUMPRODUCT(($H$7:$H$78=AE8)*($X$7:$X$78)*($F$7:$F$78))} -> 0 | BF8: =BD8-BE8 -> 0 | BG8: =BF8-MIN(BF8:BF11) -> 0 | BH8: =BB8/BB12*1000+BC8/BC12*100+BG8/BG12*10+BD8/BD12 -> 0 | BI8: =BH8/BH12 -> 0
A9: 3 | B9: {=INDEX(T,18+INT(MOD(R9-1,7)),lang)} -> Fri | C9: {=INDEX(T,24+MONTH(R9),lang) & " " & DAY(R9) & ", " & YEAR(R9)} -> Jun 12, 2026 | D9: =TIME(HOUR(R9),MINUTE(R9),0) -> 0.79166667 | E9: =AE14 -> Canada | F9: 1 | G9: 1 | H9: =AE15 -> Bosnia and Herzegovina | J9: =VLOOKUP(1,AD8:AN11,2,FALSE) -> Mexico | K9: =L9+M9+N9 -> 3 | L9: =VLOOKUP(1,AD8:AN11,3,FALSE) -> 3 | M9: =VLOOKUP(1,AD8:AN11,4,FALSE) -> 0 | N9: =VLOOKUP(1,AD8:AN11,5,FALSE) -> 0 | O9: =VLOOKUP(1,AD8:AN11,6,FALSE) & " - " & VLOOKUP(1,AD8:AN11,7,FALSE) -> 6 - 0 | P9: =L9*3+M9 -> 9 | R9: =DATE(2026,6,12)+TIME(8,0,0)+gmt_delta -> 46185.792 | S9: =IF(OR(F9="",G9=""),"",IF(F9>G9,E9&"_win",IF(F9<G9,E9&"_lose",E9&"_draw"))) -> Canada_draw | T9: =IF(S9="","",IF(F9<G9,H9&"_win",IF(F9>G9,H9&"_lose",H9&"_draw"))) -> Bosnia and Herzegovina_draw | U9: =IF(S9="",0,IF(VLOOKUP(E9,$AE$8:$AN$77,10,FALSE)=VLOOKUP(H9,$AE$8:$AN$77,10,FALSE),1,0)) -> 1 | V9: =U9*F9 -> 1 | W9: =U9*G9 -> 1 | X9: =IF(S9="",0,IF(VLOOKUP(E9,$AE$8:$AO$77,11,FALSE)=VLOOKUP(H9,$AE$8:$AO$77,11,FALSE),1,0)) -> 1 | Y9: =X9*F9 -> 1 | Z9: =X9*G9 -> 1 | AA9: =IF(OR(E9=my_team,H9=my_team),1,IF(INT(MATCH(E9,$AE$8:$AE$78,0)/6)=$AA$6,1,0)) -> 0 | AB9: =IF(OR(F9="",G9=""),"",IF(F9>G9,1,IF(F9<G9,-1,0))) -> 0 | AD9: =COUNTIF(AR8:AR11,CONCATENATE(">=",AR9)) -> 2 | AE9: =VLOOKUP("South Africa",T,lang,FALSE) -> South Africa | AF9: =COUNTIF($S$7:$T$78,"=" & AE9 & "_win") -> 1 | AG9: =COUNTIF($S$7:$T$78,"=" & AE9 & "_draw") -> 1 | AH9: =COUNTIF($S$7:$T$78,"=" & AE9 & "_lose") -> 1 | AI9: =SUMIF($E$7:$E$78,$AE9,$F$7:$F$78) + SUMIF($H$7:$H$78,$AE9,$G$7:$G$78) -> 2 | AJ9: =SUMIF($E$7:$E$78,$AE9,$G$7:$G$78) + SUMIF($H$7:$H$78,$AE9,$F$7:$F$78) -> 3 | AL9: =AI9-AJ9 -> -1 | AM9: =AL9-AL12 -> 3 | AN9: =AF9*3+AG9 -> 4 | AO9: =AN9/AN12*10+BA9 -> 4 | AP9: =AO9*10000000+BI9*100+AM9/AM12*10+AI9/AI12*1++IF(AQ9=0,ROW(),AQ9)/2000000 -> 40000003 | AQ9: =VLOOKUP(AE9,db_fifarank,2,FALSE) -> 1429.73 | AR9: =AP9/AP12 -> 0.44444442 | AS9: =IF(SUM(AF8:AH11)=12,J10,"2A") -> South Africa | AT9: {=SUMPRODUCT(($S$7:$S$78=AE9&"_win")*($U$7:$U$78))+SUMPRODUCT(($T$7:$T$78=AE9&"_win")*($U$7:$U$78))} -> 0 | AU9: {=SUMPRODUCT(($S$7:$S$78=AE9&"_draw")*($U$7:$U$78))+SUMPRODUCT(($T$7:$T$78=AE9&"_draw")*($U$7:$U$78))} -> 0 | AV9: {=SUMPRODUCT(($E$7:$E$78=AE9)*($U$7:$U$78)*($F$7:$F$78))+SUMPRODUCT(($H$7:$H$78=AE9)*($U$7:$U$78)*($G$7:$G$78))} -> 0 | AW9: {=SUMPRODUCT(($E$7:$E$78=AE9)*($U$7:$U$78)*($G$7:$G$78))+SUMPRODUCT(($H$7:$H$78=AE9)*($U$7:$U$78)*($F$7:$F$78))} -> 0 | AX9: =AV9-AW9 -> 0 | AY9: =AX9-MIN(AX8:AX11) -> 0 | AZ9: =AT9/AT12*1000+AU9/AU12*100+AY9/AY12*10+AV9/AV12 -> 0 | BA9: =AZ9/AZ12 -> 0 | BB9: {=SUMPRODUCT(($S$7:$S$78=AE9&"_win")*($X$7:$X$78))+SUMPRODUCT(($T$7:$T$78=AE9&"_win")*($X$7:$X$78))} -> 0 | BC9: {=SUMPRODUCT(($S$7:$S$78=AE9&"_draw")*($X$7:$X$78))+SUMPRODUCT(($T$7:$T$78=AE9&"_draw")*($X$7:$X$78))} -> 0 | BD9: {=SUMPRODUCT(($E$7:$E$78=AE9)*($X$7:$X$78)*($F$7:$F$78))+SUMPRODUCT(($H$7:$H$78=AE9)*($X$7:$X$78)*($G$7:$G$78))} -> 0 | BE9: {=SUMPRODUCT(($E$7:$E$78=AE9)*($X$7:$X$78)*($G$7:$G$78))+SUMPRODUCT(($H$7:$H$78=AE9)*($X$7:$X$78)*($F$7:$F$78))} -> 0 | BF9: =BD9-BE9 -> 0 | BG9: =BF9-MIN(BF8:BF11) -> 0 | BH9: =BB9/BB12*1000+BC9/BC12*100+BG9/BG12*10+BD9/BD12 -> 0 | BI9: =BH9/BH12 -> 0 | BK9: {=INDEX(T,24+MONTH(BP9),lang) & " " & DAY(BP9) & ", " & YEAR(BP9) & " " & (IF(HOUR(BP9)<10,0,"")&HOUR(BP9)) & ":" & (IF(MINUTE(BP9)<10,0,"")&MINUTE(BP9))} -> Jun 29, 2026 20:30 | BP9: =DATE(2026,6,29)+TIME(9,30,0)+gmt_delta -> 46202.854
A10: 4 | B10: {=INDEX(T,18+INT(MOD(R10-1,7)),lang)} -> Sat | C10: {=INDEX(T,24+MONTH(R10),lang) & " " & DAY(R10) & ", " & YEAR(R10)} -> Jun 13, 2026 | D10: =TIME(HOUR(R10),MINUTE(R10),0) -> 0.041666667 | E10: =AE26 -> United States | F10: 4 | G10: 1 | H10: =AE27 -> Paraguay | J10: =VLOOKUP(2,AD8:AN11,2,FALSE) -> South Africa | K10: =L10+M10+N10 -> 3 | L10: =VLOOKUP(2,AD8:AN11,3,FALSE) -> 1 | M10: =VLOOKUP(2,AD8:AN11,4,FALSE) -> 1 | N10: =VLOOKUP(2,AD8:AN11,5,FALSE) -> 1 | O10: =VLOOKUP(2,AD8:AN11,6,FALSE) & " - " & VLOOKUP(2,AD8:AN11,7,FALSE) -> 2 - 3 | P10: =L10*3+M10 -> 4 | R10: =DATE(2026,6,12)+TIME(14,0,0)+gmt_delta -> 46186.042 | S10: =IF(OR(F10="",G10=""),"",IF(F10>G10,E10&"_win",IF(F10<G10,E10&"_lose",E10&"_draw"))) -> United States_win | T10: =IF(S10="","",IF(F10<G10,H10&"_win",IF(F10>G10,H10&"_lose",H10&"_draw"))) -> Paraguay_lose | U10: =IF(S10="",0,IF(VLOOKUP(E10,$AE$8:$AN$77,10,FALSE)=VLOOKUP(H10,$AE$8:$AN$77,10,FALSE),1,0)) -> 0 | V10: =U10*F10 -> 0 | W10: =U10*G10 -> 0 | X10: =IF(S10="",0,IF(VLOOKUP(E10,$AE$8:$AO$77,11,FALSE)=VLOOKUP(H10,$AE$8:$AO$77,11,FALSE),1,0)) -> 0 | Y10: =X10*F10 -> 0 | Z10: =X10*G10 -> 0 | AA10: =IF(OR(E10=my_team,H10=my_team),1,IF(INT(MATCH(E10,$AE$8:$AE$78,0)/6)=$AA$6,1,0)) -> 0 | AB10: =IF(OR(F10="",G10=""),"",IF(F10>G10,1,IF(F10<G10,-1,0))) -> 1 | AD10: =COUNTIF(AR8:AR11,CONCATENATE(">=",AR10)) -> 3 | AE10: =VLOOKUP("Korea Republic",T,lang,FALSE) -> Korea Republic | AF10: =COUNTIF($S$7:$T$78,"=" & AE10 & "_win") -> 1 | AG10: =COUNTIF($S$7:$T$78,"=" & AE10 & "_draw") -> 0 | AH10: =COUNTIF($S$7:$T$78,"=" & AE10 & "_lose") -> 2 | AI10: =SUMIF($E$7:$E$78,$AE10,$F$7:$F$78) + SUMIF($H$7:$H$78,$AE10,$G$7:$G$78) -> 2 | AJ10: =SUMIF($E$7:$E$78,$AE10,$G$7:$G$78) + SUMIF($H$7:$H$78,$AE10,$F$7:$F$78) -> 3 | AL10: =AI10-AJ10 -> -1 | AM10: =AL10-AL12 -> 3 | AN10: =AF10*3+AG10 -> 3 | AO10: =AN10/AN12*10+BA10 -> 3 | AP10: =AO10*10000000+BI10*100+AM10/AM12*10+AI10/AI12*1++IF(AQ10=0,ROW(),AQ10)/2000000 -> 30000003 | AQ10: =VLOOKUP(AE10,db_fifarank,2,FALSE) -> 1588.66 | AR10: =AP10/AP12 -> 0.33333333 | AT10: {=SUMPRODUCT(($S$7:$S$78=AE10&"_win")*($U$7:$U$78))+SUMPRODUCT(($T$7:$T$78=AE10&"_win")*($U$7:$U$78))} -> 0 | AU10: {=SUMPRODUCT(($S$7:$S$78=AE10&"_draw")*($U$7:$U$78))+SUMPRODUCT(($T$7:$T$78=AE10&"_draw")*($U$7:$U$78))} -> 0 | AV10: {=SUMPRODUCT(($E$7:$E$78=AE10)*($U$7:$U$78)*($F$7:$F$78))+SUMPRODUCT(($H$7:$H$78=AE10)*($U$7:$U$78)*($G$7:$G$78))} -> 0 | AW10: {=SUMPRODUCT(($E$7:$E$78=AE10)*($U$7:$U$78)*($G$7:$G$78))+SUMPRODUCT(($H$7:$H$78=AE10)*($U$7:$U$78)*($F$7:$F$78))} -> 0 | AX10: =AV10-AW10 -> 0 | AY10: =AX10-MIN(AX8:AX11) -> 0 | AZ10: =AT10/AT12*1000+AU10/AU12*100+AY10/AY12*10+AV10/AV12 -> 0 | BA10: =AZ10/AZ12 -> 0 | BB10: {=SUMPRODUCT(($S$7:$S$78=AE10&"_win")*($X$7:$X$78))+SUMPRODUCT(($T$7:$T$78=AE10&"_win")*($X$7:$X$78))} -> 0 | BC10: {=SUMPRODUCT(($S$7:$S$78=AE10&"_draw")*($X$7:$X$78))+SUMPRODUCT(($T$7:$T$78=AE10&"_draw")*($X$7:$X$78))} -> 0 | BD10: {=SUMPRODUCT(($E$7:$E$78=AE10)*($X$7:$X$78)*($F$7:$F$78))+SUMPRODUCT(($H$7:$H$78=AE10)*($X$7:$X$78)*($G$7:$G$78))} -> 0 | BE10: {=SUMPRODUCT(($E$7:$E$78=AE10)*($X$7:$X$78)*($G$7:$G$78))+SUMPRODUCT(($H$7:$H$78=AE10)*($X$7:$X$78)*($F$7:$F$78))} -> 0 | BF10: =BD10-BE10 -> 0 | BG10: =BF10-MIN(BF8:BF11) -> 0 | BH10: =BB10/BB12*1000+BC10/BC12*100+BG10/BG12*10+BD10/BD12 -> 0 | BI10: =BH10/BH12 -> 0 | BK10: 74 | BL10: =AS32 -> Germany | BM10: 1 | BP10: =IF(OR(BM10="",BM11="",AND(BN10="",BN11<>""),AND(BN11="",BN10<>""),AND(BO10="",BO11<>""),AND(BO11="",BO10<>"")),"",BM10*1000+BN10*10+BO10) -> 1000
A11: 5 | B11: {=INDEX(T,18+INT(MOD(R11-1,7)),lang)} -> Sun | C11: {=INDEX(T,24+MONTH(R11),lang) & " " & DAY(R11) & ", " & YEAR(R11)} -> Jun 14, 2026 | D11: =TIME(HOUR(R11),MINUTE(R11),0) -> 0.041666667 | E11: =AE22 -> Haiti | F11: 0 | G11: 1 | H11: =AE23 -> Scotland | J11: =VLOOKUP(3,AD8:AN11,2,FALSE) -> Korea Republic | K11: =L11+M11+N11 -> 3 | L11: =VLOOKUP(3,AD8:AN11,3,FALSE) -> 1 | M11: =VLOOKUP(3,AD8:AN11,4,FALSE) -> 0 | N11: =VLOOKUP(3,AD8:AN11,5,FALSE) -> 2 | O11: =VLOOKUP(3,AD8:AN11,6,FALSE) & " - " & VLOOKUP(3,AD8:AN11,7,FALSE) -> 2 - 3 | P11: =L11*3+M11 -> 3 | R11: =DATE(2026,6,13)+TIME(14,0,0)+gmt_delta -> 46187.042 | S11: =IF(OR(F11="",G11=""),"",IF(F11>G11,E11&"_win",IF(F11<G11,E11&"_lose",E11&"_draw"))) -> Haiti_lose | T11: =IF(S11="","",IF(F11<G11,H11&"_win",IF(F11>G11,H11&"_lose",H11&"_draw"))) -> Scotland_win | U11: =IF(S11="",0,IF(VLOOKUP(E11,$AE$8:$AN$77,10,FALSE)=VLOOKUP(H11,$AE$8:$AN$77,10,FALSE),1,0)) -> 0 | V11: =U11*F11 -> 0 | W11: =U11*G11 -> 0 | X11: =IF(S11="",0,IF(VLOOKUP(E11,$AE$8:$AO$77,11,FALSE)=VLOOKUP(H11,$AE$8:$AO$77,11,FALSE),1,0)) -> 0 | Y11: =X11*F11 -> 0 | Z11: =X11*G11 -> 0 | AA11: =IF(OR(E11=my_team,H11=my_team),1,IF(INT(MATCH(E11,$AE$8:$AE$78,0)/6)=$AA$6,1,0)) -> 0 | AB11: =IF(OR(F11="",G11=""),"",IF(F11>G11,1,IF(F11<G11,-1,0))) -> -1 | AD11: =COUNTIF(AR8:AR11,CONCATENATE(">=",AR11)) -> 4 | AE11: =VLOOKUP("Czech Republic",T,lang,FALSE) -> Czech Republic | AF11: =COUNTIF($S$7:$T$78,"=" & AE11 & "_win") -> 0 | AG11: =COUNTIF($S$7:$T$78,"=" & AE11 & "_draw") -> 1 | AH11: =COUNTIF($S$7:$T$78,"=" & AE11 & "_lose") -> 2 | AI11: =SUMIF($E$7:$E$78,$AE11,$F$7:$F$78) + SUMIF($H$7:$H$78,$AE11,$G$7:$G$78) -> 2 | AJ11: =SUMIF($E$7:$E$78,$AE11,$G$7:$G$78) + SUMIF($H$7:$H$78,$AE11,$F$7:$F$78) -> 6 | AL11: =AI11-AJ11 -> -4 | AM11: =AL11-AL12 -> 0 | AN11: =AF11*3+AG11 -> 1 | AO11: =AN11/AN12*10+BA11 -> 1 | AP11: =AO11*10000000+BI11*100+AM11/AM12*10+AI11/AI12*1++IF(AQ11=0,ROW(),AQ11)/2000000 -> 10000000 | AQ11: =VLOOKUP(AE11,db_fifarank,2,FALSE) -> 1501.38 | AR11: =AP11/AP12 -> 0.1111111 | AT11: {=SUMPRODUCT(($S$7:$S$78=AE11&"_win")*($U$7:$U$78))+SUMPRODUCT(($T$7:$T$78=AE11&"_win")*($U$7:$U$78))} -> 0 | AU11: {=SUMPRODUCT(($S$7:$S$78=AE11&"_draw")*($U$7:$U$78))+SUMPRODUCT(($T$7:$T$78=AE11&"_draw")*($U$7:$U$78))} -> 0 | AV11: {=SUMPRODUCT(($E$7:$E$78=AE11)*($U$7:$U$78)*($F$7:$F$78))+SUMPRODUCT(($H$7:$H$78=AE11)*($U$7:$U$78)*($G$7:$G$78))} -> 0 | AW11: {=SUMPRODUCT(($E$7:$E$78=AE11)*($U$7:$U$78)*($G$7:$G$78))+SUMPRODUCT(($H$7:$H$78=AE11)*($U$7:$U$78)*($F$7:$F$78))} -> 0 | AX11: =AV11-AW11 -> 0 | AY11: =AX11-MIN(AX8:AX11) -> 0 | AZ11: =AT11/AT12*1000+AU11/AU12*100+AY11/AY12*10+AV11/AV12 -> 0 | BA11: =AZ11/AZ12 -> 0 | BB11: {=SUMPRODUCT(($S$7:$S$78=AE11&"_win")*($X$7:$X$78))+SUMPRODUCT(($T$7:$T$78=AE11&"_win")*($X$7:$X$78))} -> 0 | BC11: {=SUMPRODUCT(($S$7:$S$78=AE11&"_draw")*($X$7:$X$78))+SUMPRODUCT(($T$7:$T$78=AE11&"_draw")*($X$7:$X$78))} -> 0 | BD11: {=SUMPRODUCT(($E$7:$E$78=AE11)*($X$7:$X$78)*($F$7:$F$78))+SUMPRODUCT(($H$7:$H$78=AE11)*($X$7:$X$78)*($G$7:$G$78))} -> 0 | BE11: {=SUMPRODUCT(($E$7:$E$78=AE11)*($X$7:$X$78)*($G$7:$G$78))+SUMPRODUCT(($H$7:$H$78=AE11)*($X$7:$X$78)*($F$7:$F$78))} -> 0 | BF11: =BD11-BE11 -> 0 | BG11: =BF11-MIN(BF8:BF11) -> 0 | BH11: =BB11/BB12*1000+BC11/BC12*100+BG11/BG12*10+BD11/BD12 -> 0 | BI11: =BH11/BH12 -> 0 | BL11: =IF(group_round_completed,VLOOKUP('3rd places'!G3,AK80:AS91,9,FALSE),"3rd Group A/B/C/D/F") -> Paraguay | BM11: 2 | BP11: =IF(BP10="","",BM11*1000+BN11*10+BO11) -> 2000 | BR11: {=INDEX(T,24+MONTH(BW11),lang) & " " & DAY(BW11) & ", " & YEAR(BW11) & " " & (IF(HOUR(BW11)<10,0,"")&HOUR(BW11)) & ":" & (IF(MINUTE(BW11)<10,0,"")&MINUTE(BW11))} -> Jul 4, 2026 21:00 | BW11: =DATE(2026,7,4)+TIME(10,0,0)+gmt_delta -> 46207.875
A12: 6 | B12: {=INDEX(T,18+INT(MOD(R12-1,7)),lang)} -> Sun | C12: {=INDEX(T,24+MONTH(R12),lang) & " " & DAY(R12) & ", " & YEAR(R12)} -> Jun 14, 2026 | D12: =TIME(HOUR(R12),MINUTE(R12),0) -> 0.16666667 | E12: =AE28 -> Australia | F12: 2 | G12: 0 | H12: =AE29 -> Turkey | J12: =VLOOKUP(4,AD8:AN11,2,FALSE) -> Czech Republic | K12: =L12+M12+N12 -> 3 | L12: =VLOOKUP(4,AD8:AN11,3,FALSE) -> 0 | M12: =VLOOKUP(4,AD8:AN11,4,FALSE) -> 1 | N12: =VLOOKUP(4,AD8:AN11,5,FALSE) -> 2 | O12: =VLOOKUP(4,AD8:AN11,6,FALSE) & " - " & VLOOKUP(4,AD8:AN11,7,FALSE) -> 2 - 6 | P12: =L12*3+M12 -> 1 | R12: =DATE(2026,6,13)+TIME(17,0,0)+gmt_delta -> 46187.167 | S12: =IF(OR(F12="",G12=""),"",IF(F12>G12,E12&"_win",IF(F12<G12,E12&"_lose",E12&"_draw"))) -> Australia_win | T12: =IF(S12="","",IF(F12<G12,H12&"_win",IF(F12>G12,H12&"_lose",H12&"_draw"))) -> Turkey_lose | U12: =IF(S12="",0,IF(VLOOKUP(E12,$AE$8:$AN$77,10,FALSE)=VLOOKUP(H12,$AE$8:$AN$77,10,FALSE),1,0)) -> 0 | V12: =U12*F12 -> 0 | W12: =U12*G12 -> 0 | X12: =IF(S12="",0,IF(VLOOKUP(E12,$AE$8:$AO$77,11,FALSE)=VLOOKUP(H12,$AE$8:$AO$77,11,FALSE),1,0)) -> 0 | Y12: =X12*F12 -> 0 | Z12: =X12*G12 -> 0 | AA12: =IF(OR(E12=my_team,H12=my_team),1,IF(INT(MATCH(E12,$AE$8:$AE$78,0)/6)=$AA$6,1,0)) -> 0 | AB12: =IF(OR(F12="",G12=""),"",IF(F12>G12,1,IF(F12<G12,-1,0))) -> 1 | AF12: =MAX(AF8:AF11)-MIN(AF8:AF11)+1 -> 4 | AG12: =MAX(AG8:AG11)-MIN(AG8:AG11)+1 -> 2 | AH12: =MAX(AH8:AH11)-MIN(AH8:AH11)+1 -> 3 | AI12: =MAX(AI8:AI11)+1 -> 7 | AL12: =MIN(AL8:AL11) -> -4 | AM12: =MAX(AM8:AM11)+1 -> 11 | AN12: =MAX(AN8:AN11)+1 -> 10 | AO12: =MAX(AO8:AO11)+1 -> 10 | AP12: =MAX(AP8:AP11)+1 -> 90000011 | AT12: =MAX(AT8:AT11)-MIN(AT8:AT11)+1 -> 1 | AU12: =MAX(AU8:AU11)-MIN(AU8:AU11)+1 -> 1 | AV12: =MAX(AV8:AV11)-MIN(AV8:AV11)+1 -> 1 | AW12: =MAX(AW8:AW11)-MIN(AW8:AW11)+1 -> 1 | AY12: =MAX(AY8:AY11)-MIN(AY8:AY11)+1 -> 1 | AZ12: =MAX(AZ8:AZ11)+1 -> 1 | BB12: =MAX(BB8:BB11)-MIN(BB8:BB11)+1 -> 1 | BC12: =MAX(BC8:BC11)-MIN(BC8:BC11)+1 -> 1 | BD12: =MAX(BD8:BD11)-MIN(BD8:BD11)+1 -> 1 | BE12: =MAX(BE8:BE11)-MIN(BE8:BE11)+1 -> 1 | BG12: =MAX(BG8:BG11)-MIN(BG8:BG11)+1 -> 1 | BH12: =MAX(BH8:BH11)+1 -> 1 | BR12: 89 | BS12: =IF(BP10>BP11,BL10,IF(BP10<BP11,BL11,"")) -> Paraguay | BT12: 0 | BW12: =IF(OR(BT12="",BT13="",AND(BU12="",BU13<>""),AND(BU13="",BU12<>""),AND(BV12="",BV13<>""),AND(BV13="",BV12<>"")),"",BT12*1000+BU12*10+BV12) -> 0
A13: 7 | B13: {=INDEX(T,18+INT(MOD(R13-1,7)),lang)} -> Sat | C13: {=INDEX(T,24+MONTH(R13),lang) & " " & DAY(R13) & ", " & YEAR(R13)} -> Jun 13, 2026 | D13: =TIME(HOUR(R13),MINUTE(R13),0) -> 0.91666667 | E13: =AE20 -> Brazil | F13: 1 | G13: 1 | H13: =AE21 -> Morocco | R13: =DATE(2026,6,13)+TIME(11,0,0)+gmt_delta -> 46186.917 | S13: =IF(OR(F13="",G13=""),"",IF(F13>G13,E13&"_win",IF(F13<G13,E13&"_lose",E13&"_draw"))) -> Brazil_draw | T13: =IF(S13="","",IF(F13<G13,H13&"_win",IF(F13>G13,H13&"_lose",H13&"_draw"))) -> Morocco_draw | U13: =IF(S13="",0,IF(VLOOKUP(E13,$AE$8:$AN$77,10,FALSE)=VLOOKUP(H13,$AE$8:$AN$77,10,FALSE),1,0)) -> 1 | V13: =U13*F13 -> 1 | W13: =U13*G13 -> 1 | X13: =IF(S13="",0,IF(VLOOKUP(E13,$AE$8:$AO$77,11,FALSE)=VLOOKUP(H13,$AE$8:$AO$77,11,FALSE),1,0)) -> 1 | Y13: =X13*F13 -> 1 | Z13: =X13*G13 -> 1 | AA13: =IF(OR(E13=my_team,H13=my_team),1,IF(INT(MATCH(E13,$AE$8:$AE$78,0)/6)=$AA$6,1,0)) -> 0 | AB13: =IF(OR(F13="",G13=""),"",IF(F13>G13,1,IF(F13<G13,-1,0))) -> 0 | BK13: {=INDEX(T,24+MONTH(BP13),lang) & " " & DAY(BP13) & ", " & YEAR(BP13) & " " & (IF(HOUR(BP13)<10,0,"")&HOUR(BP13)) & ":" & (IF(MINUTE(BP13)<10,0,"")&MINUTE(BP13))} -> Jun 30, 2026 21:00 | BP13: =DATE(2026,6,30)+TIME(10,0,0)+gmt_delta -> 46203.875 | BS13: =IF(BP14>BP15,BL14,IF(BP14<BP15,BL15,"")) -> France | BT13: 1 | BW13: =IF(BW12="","",BT13*1000+BU13*10+BV13) -> 1000
